Workbook

Sheet Городинский
A1: Выполняемые работы | B1: Кол-во выполненной работы | C1: 46143 | D1: 46144 | E1: 46145 | F1: 46146 | G1: 46147 | H1: 46148 | I1: 46149 | J1: 46150 | K1: 46151 | L1: 46152 | M1: 46153 | N1: 46154 | O1: 46155 | P1: 46156 | Q1: 46157 | R1: 46158 | S1: 46159 | T1: 46160 | U1: 46161 | V1: 46162 | W1: 46163 | X1: 46164 | Y1: 46165 | Z1: 46166 | AA1: 46167 | AB1: 46168 | AC1: 46169 | AD1: 46170 | AE1: 46171 | AF1: 46172 | AG1: 46173 | AH1: Май | AI1: 46174 | AJ1: 46175 | AK1: 46176 | AL1: 46177 | AM1: 46178 | AN1: 46179 | AO1: 46180 | AP1: 46181 | AQ1: 46182 | AR1: 46183 | AS1: 46184 | AT1: 46185 | AU1: 46186 | AV1: 46187 | AW1: 46188 | AX1: 46189 | AY1: 46190 | AZ1: 46191 | BA1: 46192 | BB1: 46193 | BC1: 46194 | BD1: 46195 | BE1: 46196 | BF1: 46197 | BG1: 46198 | BH1: 46199 | BI1: 46200 | BJ1: 46201 | BK1: 46202 | BL1: 46203 | BM1: Июнь | BN1: 46204 | BO1: 46205 | BP1: 46206 | BQ1: 46207 | BR1: 46208 | BS1: 46209 | BT1: 46210 | BU1: 46211 | BV1: 46212 | BW1: 46213 | BX1: 46214 | BY1: 46215 | BZ1: 46216 | CA1: 46217 | CB1: 46218 | CC1: 46219 | CD1: 46220 | CE1: 46221 | CF1: 46222 | CG1: 46223 | CH1: 46224 | CI1: 46225 | CJ1: 46226 | CK1: 46227 | CL1: 46228 | CM1: 46229 | CN1: 46230 | CO1: 46231 | CP1: 46232 | CQ1: 46233 | CR1: 46234 | CS1: Июль | CT1: 46235 | CU1: 46236 | CV1: 46237 | CW1: 46238 | CX1: 46239 | CY1: 46240 | CZ1: 46241 | DA1: 46242 | DB1: 46243 | DC1: 46244 | DD1: 46245 | DE1: 46246 | DF1: 46247 | DG1: 46248 | DH1: 46249 | DI1: 46250 | DJ1: 46251 | DK1: 46252 | DL1: 46253 | DM1: 46254 | DN1: 46255 | DO1: 46256 | DP1: 46257 | DQ1: 46258 | DR1: 46259 | DS1: 46260 | DT1: 46261 | DU1: 46262 | DV1: 46263 | DW1: 46264 | DX1: 46265 | DY1: Август | DZ1: 46266 | EA1: 46267 | EB1: 46268 | EC1: 46269 | ED1: 46270 | EE1: 46271 | EF1: 46272 | EG1: 46273 | EH1: 46274 | EI1: 46275 | EJ1: 46276 | EK1: 46277 | EL1: 46278 | EM1: 46279 | EN1: 46280 | EO1: 46281 | EP1: 46282 | EQ1: 46283 | ER1: 46284 | ES1: 46285 | ET1: 46286 | EU1: 46287 | EV1: 46288 | EW1: 46289 | EX1: 46290 | EY1: 46291 | EZ1: 46292 | FA1: 46293 | FB1: 46294 | FC1: 46295 | FD1: Сентябрь | FE1: 46296 | FF1: 46297 | FG1: 46298 | FH1: 46299 | FI1: 46300 | FJ1: 46301 | FK1: 46302 | FL1: 46303 | FM1: 46304 | FN1: 46305 | FO1: 46306 | FP1: 46307 | FQ1: 46308 | FR1: 46309 | FS1: 46310 | FT1: 46311 | FU1: 46312 | FV1: 46313 | FW1: 46314 | FX1: 46315 | FY1: 46316 | FZ1: 46317 | GA1: 46318 | GB1: 46319 | GC1: 46320 | GD1: 46321 | GE1: 46322 | GF1: 46323 | GG1: 46324 | GH1: 46325 | GI1: 46326 | GJ1: Октябрь | GK1: 46327 | GL1: 46328 | GM1: 46329 | GN1: 46330 | GO1: 46331 | GP1: 46332 | GQ1: 46333 | GR1: 46334 | GS1: 46335 | GT1: 46336 | GU1: 46337 | GV1: 46338 | GW1: 46339 | GX1: 46340 | GY1: 46341 | GZ1: 46342 | HA1: 46343 | HB1: 46344 | HC1: 46345 | HD1: 46346 | HE1: 46347 | HF1: 46348 | HG1: 46349 | HH1: 46350 | HI1: 46351 | HJ1: 46352 | HK1: 46353 | HL1: 46354 | HM1: 46355 | HN1: 46356 | HO1: Ноябрь | HP1: 46357 | HQ1: 46358 | HR1: 46359 | HS1: 46360 | HT1: 46361 | HU1: 46362 | HV1: 46363 | HW1: 46364 | HX1: 46365 | HY1: 46366 | HZ1: 46367 | IA1: 46368 | IB1: 46369 | IC1: 46370 | ID1: 46371 | IE1: 46372 | IF1: 46373 | IG1: 46374 | IH1: 46375 | II1: 46376 | IJ1: 46377 | IK1: 46378 | IL1: 46379 | IM1: 46380 | IN1: 46381 | IO1: 46382 | IP1: 46383 | IQ1: 46384 | IR1: 46385 | IS1: 46386 | IT1: 46387 | IU1: Декабрь | IV1: Всё
A2: Создание нового объекта в АРМ "Наружные сети", МПК "Панорама", внесение графического изображения газопровода и смежных коммуникаций, настройка связей, внесение электронного варианта ИТД | B2: м. | AH2: =SUM(C2:AG2) -> 0 | AK2: 53.29 | AL2: 55.03 | AX2: 80.61 | BD2: 16.41 | BE2: 10.17 | BF2: 9.84 | BG2: 26.97 | BH2: 60.11 | BK2: 26.98 | BL2: 119.41 | BM2: =SUM(AI2:BL2) -> 350.5 | BN2: 80.95 | BO2: 0.8 | BT2: 11.1 | BU2: 25.86 | CA2: 8.97 | CB2: 32.68 | CS2: =SUM(BN2:CR2) -> 160.36 | DK2: 37.15 | DL2: 31.85 | DQ2: 8.4 | DR2: 18.57 | DS2: 36.76 | DT2: 44.11 | DY2: =SUM(CT2:DX2) -> 176.84 | EB2: 31.9 | EG2: 38.3 | EN2: 21.1 | EQ2: 198.92 | FD2: =SUM(DZ2:FC2) -> 290.22 | GJ2: =SUM(FE2:GI2) -> 0 | HO2: =SUM(GK2:HN2) -> 0 | IT2: 1500 | IU2: =SUM(HP2:IT2) -> 1500 | IV2: =SUM(AH2,BM2,CS2,DY2,FD2,GJ2,HO2,IU2) -> 2477.92
A3: Внесение в 7эг, МПК "Панорама" актов на ликвидацию | B3: шт. | C3: 3 | AH3: =SUM(C3:AG3) -> 3 | AJ3: 1 | AK3: 1 | BM3: =SUM(AI3:BL3) -> 2 | CS3: =SUM(BN3:CR3) -> 0 | DQ3: 1 | DT3: 1 | DY3: =SUM(CT3:DX3) -> 2 | FD3: =SUM(DZ3:FC3) -> 0 | GJ3: =SUM(FE3:GI3) -> 0 | HO3: =SUM(GK3:HN3) -> 0 | IT3: 51 | IU3: =SUM(HP3:IT3) -> 51 | IV3: =SUM(AH3,BM3,CS3,DY3,FD3,GJ3,HO3,IU3) -> 58
A4: Сканирование нарядов, размещение в электронный архив | B4: шт. | C4: 26 | AH4: =SUM(C4:AG4) -> 26 | AI4: 2 | AJ4: 1 | AL4: 1 | AX4: 2 | BE4: 1 | BG4: 6 | BH4: 1 | BK4: 3 | BM4: =SUM(AI4:BL4) -> 17 | CS4: =SUM(BN4:CR4) -> 0 | DY4: =SUM(CT4:DX4) -> 0 | FD4: =SUM(DZ4:FC4) -> 0 | GJ4: =SUM(FE4:GI4) -> 0 | HO4: =SUM(GK4:HN4) -> 0 | IT4: 128 | IU4: =SUM(HP4:IT4) -> 128 | IV4: =SUM(AH4,BM4,CS4,DY4,FD4,GJ4,HO4,IU4) -> 171
A5: Внесение нарядов в программные комплексы | B5: шт. | C5: 26 | AH5: =SUM(C5:AG5) -> 26 | AI5: 2 | AJ5: 1 | AL5: 1 | AX5: 2 | BE5: 1 | BG5: 6 | BH5: 1 | BK5: 3 | BM5: =SUM(AI5:BL5) -> 17 | CS5: =SUM(BN5:CR5) -> 0 | DY5: =SUM(CT5:DX5) -> 0 | FD5: =SUM(DZ5:FC5) -> 0 | GJ5: =SUM(FE5:GI5) -> 0 | HO5: =SUM(GK5:HN5) -> 0 | IT5: 129 | IU5: =SUM(HP5:IT5) -> 129 | IV5: =SUM(AH5,BM5,CS5,DY5,FD5,GJ5,HO5,IU5) -> 172
A6: Исправление замечаний в 7эг | B6: шт. | AH6: =SUM(C6:AG6) -> 0 | BM6: =SUM(AI6:BL6) -> 0 | CS6: =SUM(BN6:CR6) -> 0 | DY6: =SUM(CT6:DX6) -> 0 | FD6: =SUM(DZ6:FC6) -> 0 | GJ6: =SUM(FE6:GI6) -> 0 | HO6: =SUM(GK6:HN6) -> 0 | IT6: 30 | IU6: =SUM(HP6:IT6) -> 30 | IV6: =SUM(AH6,BM6,CS6,DY6,FD6,GJ6,HO6,IU6) -> 30
A7: Исправление замечаний в МПК Панорама | B7: шт. | AH7: =SUM(C7:AG7) -> 0 | BK7: 1 | BM7: =SUM(AI7:BL7) -> 1 | CJ7: 1 | CS7: =SUM(BN7:CR7) -> 1 | DY7: =SUM(CT7:DX7) -> 0 | FD7: =SUM(DZ7:FC7) -> 0 | GJ7: =SUM(FE7:GI7) -> 0 | HO7: =SUM(GK7:HN7) -> 0 | IT7: 31 | IU7: =SUM(HP7:IT7) -> 31 | IV7: =SUM(AH7,BM7,CS7,DY7,FD7,GJ7,HO7,IU7) -> 33
A8: Инвентаризация паспортов | B8: Арх. № (пунктов) | AH8: =SUM(C8:AG8) -> 0 | BM8: =SUM(AI8:BL8) -> 0 | CS8: =SUM(BN8:CR8) -> 0 | DY8: =SUM(CT8:DX8) -> 0 | FD8: =SUM(DZ8:FC8) -> 0 | GJ8: =SUM(FE8:GI8) -> 0 | HO8: =SUM(GK8:HN8) -> 0 | IT8: 5 | IU8: =SUM(HP8:IT8) -> 5 | IV8: =SUM(AH8,BM8,CS8,DY8,FD8,GJ8,HO8,IU8) -> 5
A9: Сканирование документации (листов) | B9: шт. | C9: 27 | AH9: =SUM(C9:AG9) -> 27 | AI9: 8 | AK9: 8 | AL9: 8 | AX9: 15 | BD9: 5 | BE9: 5 | BF9: 5 | BG9: 25 | BH9: 7 | BK9: 7 | BL9: 18 | BM9: =SUM(AI9:BL9) -> 111 | BN9: 12 | BO9: 4 | BT9: 6 | BU9: 6 | CA9: 6 | CB9: 6 | CN9: 208 | CO9: 6 | CS9: =SUM(BN9:CR9) -> 254 | CX9: 178 | DC9: 9 | DK9: 35 | DN9: 18 | DQ9: 17 | DS9: 33 | DY9: =SUM(CT9:DX9) -> 290 | DZ9: 3 | EA9: 19 | EF9: 21 | EM9: 10 | EQ9: 10 | FD9: =SUM(DZ9:FC9) -> 63 | FF9: 15 | GJ9: =SUM(FE9:GI9) -> 15 | HO9: =SUM(GK9:HN9) -> 0 | IT9: 433 | IU9: =SUM(HP9:IT9) -> 433 | IV9: =SUM(AH9,BM9,CS9,DY9,FD9,GJ9,HO9,IU9) -> 1193
A10: Прикрепление файлов итд в 7 ЭГ | B10: шт. | C10: 43 | AH10: =SUM(C10:AG10) -> 43 | AI10: 8 | AK10: 8 | AL10: 8 | AX10: 15 | BD10: 5 | BE10: 5 | BF10: 5 | BG10: 25 | BH10: 7 | BK10: 7 | BL10: 18 | BM10: =SUM(AI10:BL10) -> 111 | BN10: 12 | BO10: 4 | BT10: 6 | BU10: 6 | CA10: 6 | CB10: 6 | CN10: 9 | CO10: 6 | CS10: =SUM(BN10:CR10) -> 55 | DK10: 7 | DL10: 7 | DN10: 3 | DQ10: 6 | DR10: 11 | DS10: 4 | DT10: 10 | DY10: =SUM(CT10:DX10) -> 48 | EB10: 11 | EN10: 6 | EQ10: 5 | FD10: =SUM(DZ10:FC10) -> 22 | GJ10: =SUM(FE10:GI10) -> 0 | HO10: =SUM(GK10:HN10) -> 0 | IT10: 409 | IU10: =SUM(HP10:IT10) -> 409 | IV10: =SUM(AH10,BM10,CS10,DY10,FD10,GJ10,HO10,IU10) -> 688
A11: Связь графика КПО с картой КПО | B11: шт. | AH11: =SUM(C11:AG11) -> 0 | BM11: =SUM(AI11:BL11) -> 0 | CS11: =SUM(BN11:CR11) -> 0 | DY11: =SUM(CT11:DX11) -> 0 | FD11: =SUM(DZ11:FC11) -> 0 | GJ11: =SUM(FE11:GI11) -> 0 | HO11: =SUM(GK11:HN11) -> 0 | IT11: 220 | IU11: =SUM(HP11:IT11) -> 220 | IV11: =SUM(AH11,BM11,CS11,DY11,FD11,GJ11,HO11,IU11) -> 220
A12: Отрисовка фитингов в МПК Панорама | B12: шт. | AH12: =SUM(C12:AG12) -> 0 | BM12: =SUM(AI12:BL12) -> 0 | CS12: =SUM(BN12:CR12) -> 0 | DY12: =SUM(CT12:DX12) -> 0 | FD12: =SUM(DZ12:FC12) -> 0 | GJ12: =SUM(FE12:GI12) -> 0 | HO12: =SUM(GK12:HN12) -> 0 | IT12: 6 | IU12: =SUM(HP12:IT12) -> 6 | IV12: =SUM(AH12,BM12,CS12,DY12,FD12,GJ12,HO12,IU12) -> 6
A13: Нанесение подвалов в МПК "Панорама" | B13: шт. | AH13: =SUM(C13:AG13) -> 0 | BM13: =SUM(AI13:BL13) -> 0 | CS13: =SUM(BN13:CR13) -> 0 | DY13: =SUM(CT13:DX13) -> 0 | FD13: =SUM(DZ13:FC13) -> 0 | GJ13: =SUM(FE13:GI13) -> 0 | HO13: =SUM(GK13:HN13) -> 0 | IT13: 156 | IU13: =SUM(HP13:IT13) -> 156 | IV13: =SUM(AH13,BM13,CS13,DY13,FD13,GJ13,HO13,IU13) -> 156
A14: Исправление ошибок по целостности газопроводов | B14: шт. | AH14: =SUM(C14:AG14) -> 0 | BM14: =SUM(AI14:BL14) -> 0 | CS14: =SUM(BN14:CR14) -> 0 | DY14: =SUM(CT14:DX14) -> 0 | FD14: =SUM(DZ14:FC14) -> 0 | GJ14: =SUM(FE14:GI14) -> 0 | HO14: =SUM(GK14:HN14) -> 0 | IT14: 108 | IU14: =SUM(HP14:IT14) -> 108 | IV14: =SUM(AH14,BM14,CS14,DY14,FD14,GJ14,HO14,IU14) -> 108
A15: Заполнение карточки на кран на газопроводе-вводе | B15: шт. | AH15: =SUM(C15:AG15) -> 0 | BM15: =SUM(AI15:BL15) -> 0 | BN15: 2 | BO15: 1 | BT15: 1 | BU15: 1 | CA15: 1 | CB15: 1 | CN15: 26 | CO15: 32 | CS15: =SUM(BN15:CR15) -> 65 | CX15: 1 | DC15: 43 | DD15: 40 | DE15: 75 | DF15: 102 | DG15: 17 | DJ15: 70 | DK15: 9 | DL15: 12 | DM15: 65 | DN15: 43 | DQ15: 1 | DR15: 2 | DS15: 2 | DT15: 5 | DU15: 27 | DX15: 53 | DY15: =SUM(CT15:DX15) -> 567 | DZ15: 45 | EA15: 48 | EB15: 9 | EC15: 41 | EF15: 47 | EG15: 26 | EH15: 51 | EI15: 43 | EJ15: 28 | EM15: 45 | EN15: 33 | EO15: 59 | EP15: 53 | EQ15: 2 | FD15: =SUM(DZ15:FC15) -> 530 | FE15: 45 | GJ15: =SUM(FE15:GI15) -> 45 | HO15: =SUM(GK15:HN15) -> 0 | IT15: 750 | IU15: =SUM(HP15:IT15) -> 750 | IV15: =SUM(AH15,BM15,CS15,DY15,FD15,GJ15,HO15,IU15) -> 1957
A16: Демонтаж газопроводов | B16: Арх. № (пунктов) | AH16: =SUM(C16:AG16) -> 0 | BM16: =SUM(AI16:BL16) -> 0 | CS16: =SUM(BN16:CR16) -> 0 | DY16: =SUM(CT16:DX16) -> 0 | FD16: =SUM(DZ16:FC16) -> 0 | GJ16: =SUM(FE16:GI16) -> 0 | HO16: =SUM(GK16:HN16) -> 0 | IU16: =SUM(HP16:IT16) -> 0 | IV16: =SUM(AH16,BM16,CS16,DY16,FD16,GJ16,HO16,IU16) -> 0
A17: Инвентаризация запорных устройств | B17: шт. | C17: 23 | AH17: =SUM(C17:AG17) -> 23 | AI17: 3 | AJ17: 12 | AL17: 1 | BM17: =SUM(AI17:BL17) -> 16 | IV17: =SUM(AH17,BM17,CS17,DY17,FD17,GJ17,HO17,IU17) -> 39
A18: Иные работы | B18: шт. | AH18: =SUM(C18:AG18) -> 0 | AL18: 16 | AM18: 27 | AP18: 37 | AQ18: 50 | AR18: 41 | AS18: 53 | AT18: 39 | AW18: 49 | AY18: 13 | AZ18: 18 | BA18: 25 | BD18: 13 | BE18: 12 | BF18: 70 | BM18: =SUM(AI18:BL18) -> 463 | BO18: 15 | BS18: 33 | BT18: 19 | BU18: 28 | BV18: 45 | BW18: 41 | BZ18: 39 | CA18: 17 | CB18: 23 | CC18: 180 | CD18: 100 | CG18: 21 | CH18: 35 | CI18: 153 | CJ18: 61 | CK18: 46 | CN18: 59 | CP18: 320 | CQ18: 257 | CR18: 243 | CS18: =SUM(BN18:CR18) -> 1735 | CW18: 598 | CZ18: 15 | DC18: 21 | DD18: 10 | DJ18: 5 | DQ18: 8 | DU18: 9 | DX18: 5 | DY18: =SUM(CT18:DX18) -> 671 | DZ18: 7 | EA18: 8 | EI18: 5 | EJ18: 10 | FD18: =SUM(DZ18:FC18) -> 30 | FE18: 15 | FF18: 20 | GJ18: =SUM(FE18:GI18) -> 35 | HO18: =SUM(GK18:HN18) -> 0 | IU18: =SUM(HP18:IT18) -> 0 | IV18: =SUM(AH18,BM18,CS18,DY18,FD18,GJ18,HO18,IU18) -> 2934
A19: Внесение вновь принятого объекта в ПК УРГ | B19: шт. | AH19: =SUM(C19:AG19) -> 0 | BM19: =SUM(AI19:BL19) -> 0 | CS19: =SUM(BN19:CR19) -> 0 | CY19: 2 | DY19: =SUM(CT19:DX19) -> 2 | FD19: =SUM(DZ19:FC19) -> 0 | FE19: 1 | FF19: 1 | FI19: 2 | GJ19: =SUM(FE19:GI19) -> 4 | HO19: =SUM(GK19:HN19) -> 0 | IU19: =SUM(HP19:IT19) -> 0 | IV19: =SUM(AH19,BM19,CS19,DY19,FD19,GJ19,HO19,IU19) -> 6
A20: Оформление эксплуатационного паспорта в ПК УРГ | B20: шт. | AH20: =SUM(C20:AG20) -> 0 | BM20: =SUM(AI20:BL20) -> 0 | CS20: =SUM(BN20:CR20) -> 0 | CY20: 2 | DY20: =SUM(CT20:DX20) -> 2 | FD20: =SUM(DZ20:FC20) -> 0 | FE20: 1 | FF20: 1 | FI20: 2 | GJ20: =SUM(FE20:GI20) -> 4 | HO20: =SUM(GK20:HN20) -> 0 | IU20: =SUM(HP20:IT20) -> 0 | IV20: =SUM(AH20,BM20,CS20,DY20,FD20,GJ20,HO20,IU20) -> 6
A21: Инвентаризация объектов ПК УРГ | B21: шт. | AH21: =SUM(C21:AG21) -> 0 | BM21: =SUM(AI21:BL21) -> 0 | CS21: =SUM(BN21:CR21) -> 0 | DY21: =SUM(CT21:DX21) -> 0 | FD21: =SUM(DZ21:FC21) -> 0 | GJ21: =SUM(FE21:GI21) -> 0 | HO21: =SUM(GK21:HN21) -> 0 | IU21: =SUM(HP21:IT21) -> 0 | IV21: =SUM(AH21,BM21,CS21,DY21,FD21,GJ21,HO21,IU21) -> 0
A22: Прикрепление файлов в ПК УРГ | B22: шт. | AH22: =SUM(C22:AG22) -> 0 | BM22: =SUM(AI22:BL22) -> 0 | CC22: 210 | CD22: 200 | CS22: =SUM(BN22:CR22) -> 410 | CX22: 9 | CY22: 111 | CZ22: 47 | DC22: 29 | DD22: 8 | DY22: =SUM(CT22:DX22) -> 204 | FD22: =SUM(DZ22:FC22) -> 0 | FF22: 81 | FI22: 55 | GJ22: =SUM(FE22:GI22) -> 136 | HO22: =SUM(GK22:HN22) -> 0 | IU22: =SUM(HP22:IT22) -> 0 | IV22: =SUM(AH22,BM22,CS22,DY22,FD22,GJ22,HO22,IU22) -> 750
A23: Сканирование документации в ПК УРГ | B23: шт. | AH23: =SUM(C23:AG23) -> 0 | AJ23: 1 | BM23: =SUM(AI23:BL23) -> 1 | CA23: 1 | CS23: =SUM(BN23:CR23) -> 1 | CX23: 1 | CY23: 1 | CZ23: 2 | DG23: 2 | DY23: =SUM(CT23:DX23) -> 6 | FD23: =SUM(DZ23:FC23) -> 0 | GJ23: =SUM(FE23:GI23) -> 0 | HO23: =SUM(GK23:HN23) -> 0 | IU23: =SUM(HP23:IT23) -> 0 | IV23: =SUM(AH23,BM23,CS23,DY23,FD23,GJ23,HO23,IU23) -> 8
A24: Ликвидация неактуальной документации и фотоматериалов в ПК УРГ | B24: шт. | AH24: =SUM(C24:AG24) -> 0 | BM24: =SUM(AI24:BL24) -> 0 | CS24: =SUM(BN24:CR24) -> 0 | CY24: 110 | CZ24: 9 | DC24: 23 | DY24: =SUM(CT24:DX24) -> 142 | FD24: =SUM(DZ24:FC24) -> 0 | FF24: 23 | FI24: 105 | GJ24: =SUM(FE24:GI24) -> 128 | HO24: =SUM(GK24:HN24) -> 0 | IU24: =SUM(HP24:IT24) -> 0 | IV24: =SUM(AH24,BM24,CS24,DY24,FD24,GJ24,HO24,IU24) -> 270
AL25: 22

Sheet Горох
A1: Выполняемые работы | B1: Кол-во выполненной работы | C1: 46143 | D1: 46144 | E1: 46145 | F1: 46146 | G1: 46147 | H1: 46148 | I1: 46149 | J1: 46150 | K1: 46151 | L1: 46152 | M1: 46153 | N1: 46154 | O1: 46155 | P1: 46156 | Q1: 46157 | R1: 46158 | S1: 46159 | T1: 46160 | U1: 46161 | V1: 46162 | W1: 46163 | X1: 46164 | Y1: 46165 | Z1: 46166 | AA1: 46167 | AB1: 46168 | AC1: 46169 | AD1: 46170 | AE1: 46171 | AF1: 46172 | AG1: 46173 | AH1: Май | AI1: 46174 | AJ1: 46175 | AK1: 46176 | AL1: 46177 | AM1: 46178 | AN1: 46179 | AO1: 46180 | AP1: 46181 | AQ1: 46182 | AR1: 46183 | AS1: 46184 | AT1: 46185 | AU1: 46186 | AV1: 46187 | AW1: 46188 | AX1: 46189 | AY1: 46190 | AZ1: 46191 | BA1: 46192 | BB1: 46193 | BC1: 46194 | BD1: 46195 | BE1: 46196 | BF1: 46197 | BG1: 46198 | BH1: 46199 | BI1: 46200 | BJ1: 46201 | BK1: 46202 | BL1: 46203 | BM1: Июнь | BN1: 46204 | BO1: 46205 | BP1: 46206 | BQ1: 46207 | BR1: 46208 | BS1: 46209 | BT1: 46210 | BU1: 46211 | BV1: 46212 | BW1: 46213 | BX1: 46214 | BY1: 46215 | BZ1: 46216 | CA1: 46217 | CB1: 46218 | CC1: 46219 | CD1: 46220 | CE1: 46221 | CF1: 46222 | CG1: 46223 | CH1: 46224 | CI1: 46225 | CJ1: 46226 | CK1: 46227 | CL1: 46228 | CM1: 46229 | CN1: 46230 | CO1: 46231 | CP1: 46232 | CQ1: 46233 | CR1: 46234 | CS1: Июль | CT1: 46235 | CU1: 46236 | CV1: 46237 | CW1: 46238 | CX1: 46239 | CY1: 46240 | CZ1: 46241 | DA1: 46242 | DB1: 46243 | DC1: 46244 | DD1: 46245 | DE1: 46246 | DF1: 46247 | DG1: 46248 | DH1: 46249 | DI1: 46250 | DJ1: 46251 | DK1: 46252 | DL1: 46253 | DM1: 46254 | DN1: 46255 | DO1: 46256 | DP1: 46257 | DQ1: 46258 | DR1: 46259 | DS1: 46260 | DT1: 46261 | DU1: 46262 | DV1: 46263 | DW1: 46264 | DX1: 46265 | DY1: Август | DZ1: 46266 | EA1: 46267 | EB1: 46268 | EC1: 46269 | ED1: 46270 | EE1: 46271 | EF1: 46272 | EG1: 46273 | EH1: 46274 | EI1: 46275 | EJ1: 46276 | EK1: 46277 | EL1: 46278 | EM1: 46279 | EN1: 46280 | EO1: 46281 | EP1: 46282 | EQ1: 46283 | ER1: 46284 | ES1: 46285 | ET1: 46286 | EU1: 46287 | EV1: 46288 | EW1: 46289 | EX1: 46290 | EY1: 46291 | EZ1: 46292 | FA1: 46293 | FB1: 46294 | FC1: 46295 | FD1: Сентябрь | FE1: 46296 | FF1: 46297 | FG1: 46298 | FH1: 46299 | FI1: 46300 | FJ1: 46301 | FK1: 46302 | FL1: 46303 | FM1: 46304 | FN1: 46305 | FO1: 46306 | FP1: 46307 | FQ1: 46308 | FR1: 46309 | FS1: 46310 | FT1: 46311 | FU1: 46312 | FV1: 46313 | FW1: 46314 | FX1: 46315 | FY1: 46316 | FZ1: 46317 | GA1: 46318 | GB1: 46319 | GC1: 46320 | GD1: 46321 | GE1: 46322 | GF1: 46323 | GG1: 46324 | GH1: 46325 | GI1: 46326 | GJ1: Октябрь | GK1: 46327 | GL1: 46328 | GM1: 46329 | GN1: 46330 | GO1: 46331 | GP1: 46332 | GQ1: 46333 | GR1: 46334 | GS1: 46335 | GT1: 46336 | GU1: 46337 | GV1: 46338 | GW1: 46339 | GX1: 46340 | GY1: 46341 | GZ1: 46342 | HA1: 46343 | HB1: 46344 | HC1: 46345 | HD1: 46346 | HE1: 46347 | HF1: 46348 | HG1: 46349 | HH1: 46350 | HI1: 46351 | HJ1: 46352 | HK1: 46353 | HL1: 46354 | HM1: 46355 | HN1: 46356 | HO1: Ноябрь | HP1: 46357 | HQ1: 46358 | HR1: 46359 | HS1: 46360 | HT1: 46361 | HU1: 46362 | HV1: 46363 | HW1: 46364 | HX1: 46365 | HY1: 46366 | HZ1: 46367 | IA1: 46368 | IB1: 46369 | IC1: 46370 | ID1: 46371 | IE1: 46372 | IF1: 46373 | IG1: 46374 | IH1: 46375 | II1: 46376 | IJ1: 46377 | IK1: 46378 | IL1: 46379 | IM1: 46380 | IN1: 46381 | IO1: 46382 | IP1: 46383 | IQ1: 46384 | IR1: 46385 | IS1: 46386 | IT1: 46387 | IU1: Декабрь | IV1: Всё
A2: Создание нового объекта в АРМ "Наружные сети", МПК "Панорама", внесение графического изображения газопровода и смежных коммуникация, настройка связей, внесение электронного варианта ИТД | B2: м. | C2: 567.55 | AH2: =SUM(C2:AG2) -> 567.55 | AM2: 102.93 | AP2: 1 | AS2: 4 | AT2: 183.58 | AW2: 302.62 | AX2: 142.79 | BD2: все на смарку | BE2: 448.46 | BM2: =SUM(AI2:BL2) -> 1185.38 | BZ2: 2.612 | CA2: 103.92 | CB2: 99.05 | CD2: 51.92 | CG2: 496.08 | CH2: 25.14 | CO2: 23.1 | CP2: 74.74 | CS2: =SUM(BN2:CR2) -> 876.562 | CV2: 60.94 | CY2: 5.78 | DC2: 13.96 | DD2: 34.02 | DF2: 9.03 | DK2: 76.36 | DL2: 1.47 | DM2: 68.04 | DS2: 8.95 | DY2: =SUM(CT2:DX2) -> 278.55 | EB2: 43.77 | EF2: 134.155 | EG2: 134.155 | EH2: 891.89 | EI2: 90.76 | EN2: 40.56 | EQ2: 10.27 | ET2: 147.59 | EU2: 8.65 | EW2: 51.99 | EX2: 15.18 | FB2: 116.27 | FC2: 28.75 | FD2: =SUM(DZ2:FC2) -> 1713.99 | FE2: 110.78 | GJ2: =SUM(FE2:GI2) -> 110.78 | HO2: =SUM(GK2:HN2) -> 0 | IT2: 1500 | IU2: =SUM(HP2:IT2) -> 1500 | IV2: =SUM(AH2,BM2,CS2,DY2,FD2,GJ2,HO2,IU2) -> 6232.812
A3: Внесение в 7эг, МПК "Панорама" актов на ликвидацию | B3: шт. | C3: 93 | AH3: =SUM(C3:AG3) -> 93 | AK3: 1 | BM3: =SUM(AI3:BL3) -> 1 | CA3: 3 | CN3: 2 | CQ3: 1 | CR3: 2 | CS3: =SUM(BN3:CR3) -> 8 | DG3: 1 | DL3: 1 | DS3: 1 | DY3: =SUM(CT3:DX3) -> 3 | EH3: 1 | EW3: 2 | FA3: 1 | FD3: =SUM(DZ3:FC3) -> 4 | GJ3: =SUM(FE3:GI3) -> 0 | HO3: =SUM(GK3:HN3) -> 0 | IT3: 51 | IU3: =SUM(HP3:IT3) -> 51 | IV3: =SUM(AH3,BM3,CS3,DY3,FD3,GJ3,HO3,IU3) -> 160
A4: Сканирование нарядов, размещение в электронный архив | B4: шт. | C4: 61 | AH4: =SUM(C4:AG4) -> 61 | AI4: 5 | AJ4: 5 | AM4: 1 | AP4: 1 | AQ4: 3 | AS4: 3 | AT4: 4 | AW4: 3 | AX4: 1 | BA4: 5 | BD4: 1 | BE4: 2 | BM4: =SUM(AI4:BL4) -> 34 | CB4: 2 | CC4: 9 | CD4: 17 | CI4: 4 | CJ4: 4 | CK4: 4 | CN4: 12 | CO4: 8 | CQ4: 4 | CR4: 9 | CS4: =SUM(BN4:CR4) -> 73 | CW4: 12 | CY4: 1 | DF4: 6 | DK4: 1 | DY4: =SUM(CT4:DX4) -> 20 | EG4: 1 | EM4: 2 | EO4: 2 | EP4: 1 | EQ4: 2 | ET4: 3 | EU4: 5 | EW4: 4 | EX4: 7 | FA4: 10 | FC4: 5 | FD4: =SUM(DZ4:FC4) -> 42 | FE4: 2 | FF4: 2 | GJ4: =SUM(FE4:GI4) -> 4 | HO4: =SUM(GK4:HN4) -> 0 | IT4: 128 | IU4: =SUM(HP4:IT4) -> 128 | IV4: =SUM(AH4,BM4,CS4,DY4,FD4,GJ4,HO4,IU4) -> 362
A5: Внесение нарядов в программные комплексы | B5: шт. | C5: 93 | AH5: =SUM(C5:AG5) -> 93 | AI5: 5 | AJ5: 5 | AM5: 1 | AP5: 1 | AQ5: 3 | AS5: 3 | AT5: 4 | AW5: 3 | AX5: 1 | BA5: 5 | BD5: 1 | BE5: 4 | BM5: =SUM(AI5:BL5) -> 36 | CB5: 2 | CC5: 9 | CD5: 17 | CI5: 4 | CJ5: 4 | CK5: 5 | CN5: 12 | CO5: 8 | CQ5: 4 | CR5: 9 | CS5: =SUM(BN5:CR5) -> 74 | CW5: 12 | CX5: 8 | CY5: 10 | CZ5: 6 | DC5: 6 | DF5: 6 | DK5: 1 | DT5: 1 | DU5: 5 | DY5: =SUM(CT5:DX5) -> 55 | EC5: 1 | EG5: 1 | EO5: 2 | EP5: 1 | EQ5: 2 | ET5: 3 | EU5: 5 | EW5: 4 | EX5: 7 | FA5: 10 | FC5: 5 | FD5: =SUM(DZ5:FC5) -> 41 | FE5: 2 | FF5: 2 | GJ5: =SUM(FE5:GI5) -> 4 | HO5: =SUM(GK5:HN5) -> 0 | IT5: 129 | IU5: =SUM(HP5:IT5) -> 129 | IV5: =SUM(AH5,BM5,CS5,DY5,FD5,GJ5,HO5,IU5) -> 432
A6: Исправление замечаний в 7эг | B6: шт. | C6: 3 | AH6: =SUM(C6:AG6) -> 3 | AT6: 1 | AW6: 1 | AY6: 12 | BM6: =SUM(AI6:BL6) -> 14 | CB6: 2 | CQ6: 2 | CS6: =SUM(BN6:CR6) -> 4 | CX6: 8 | CY6: 10 | CZ6: 6 | DS6: 3 | DY6: =SUM(CT6:DX6) -> 27 | EA6: 1 | FD6: =SUM(DZ6:FC6) -> 1 | GJ6: =SUM(FE6:GI6) -> 0 | HO6: =SUM(GK6:HN6) -> 0 | IT6: 30 | IU6: =SUM(HP6:IT6) -> 30 | IV6: =SUM(AH6,BM6,CS6,DY6,FD6,GJ6,HO6,IU6) -> 79
A7: Исправление замечаний в МПК Панорама | B7: шт. | AH7: =SUM(C7:AG7) -> 0 | BM7: =SUM(AI7:BL7) -> 0 | CH7: 7 | CS7: =SUM(BN7:CR7) -> 7 | DT7: 8 | DY7: =SUM(CT7:DX7) -> 8 | DZ7: 1 | EW7: 12 | FA7: 4 | FD7: =SUM(DZ7:FC7) -> 17 | GJ7: =SUM(FE7:GI7) -> 0 | HO7: =SUM(GK7:HN7) -> 0 | IT7: 31 | IU7: =SUM(HP7:IT7) -> 31 | IV7: =SUM(AH7,BM7,CS7,DY7,FD7,GJ7,HO7,IU7) -> 63
A8: Инвентаризация паспортов | B8: Арх. № (пунктов) | C8: 3 | AH8: =SUM(C8:AG8) -> 3 | BM8: =SUM(AI8:BL8) -> 0 | CO8: 2 | CP8: 1 | CR8: 1 | CS8: =SUM(BN8:CR8) -> 4 | DE8: 1 | DG8: 1 | DK8: 1 | DL8: 2 | DY8: =SUM(CT8:DX8) -> 5 | EM8: 1 | EP8: 1 | EV8: 5 | FA8: 1 | FD8: =SUM(DZ8:FC8) -> 8 | GJ8: =SUM(FE8:GI8) -> 0 | HO8: =SUM(GK8:HN8) -> 0 | IT8: 5 | IU8: =SUM(HP8:IT8) -> 5 | IV8: =SUM(AH8,BM8,CS8,DY8,FD8,GJ8,HO8,IU8) -> 25
A9: Сканирование документации (листов) | B9: шт. | C9: 184 | AH9: =SUM(C9:AG9) -> 184 | AI9: 10 | AK9: 8 | AM9: 15 | AP9: 4 | AS9: 23 | AT9: 20 | BE9: 6 | BM9: =SUM(AI9:BL9) -> 86 | CA9: 8 | CB9: 4 | CG9: 20 | CH9: 20 | CO9: 10 | CP9: 18 | CS9: =SUM(BN9:CR9) -> 80 | DD9: 8 | DE9: 3 | DG9: 3 | DK9: 3 | DL9: 5 | DM9: 6 | DY9: =SUM(CT9:DX9) -> 28 | EB9: 10 | EM9: 19 | EP9: 5 | EQ9: 5 | ET9: 11 | EU9: 5 | FB9: 24 | FC9: 6 | FD9: =SUM(DZ9:FC9) -> 85 | FE9: 6 | GJ9: =SUM(FE9:GI9) -> 6 | HO9: =SUM(GK9:HN9) -> 0 | IT9: 433 | IU9: =SUM(HP9:IT9) -> 433 | IV9: =SUM(AH9,BM9,CS9,DY9,FD9,GJ9,HO9,IU9) -> 902
A10: Прикрепление файлов итд в 7 ЭГ | B10: шт. | AH10: =SUM(C10:AG10) -> 0 | AI10: 10 | AK10: 8 | AM10: 15 | AP10: 4 | AS10: 23 | AT10: 20 | AW10: 10 | AX10: 10 | BD10: 6 | BE10: 12 | BF10: 8 | BM10: =SUM(AI10:BL10) -> 126 | BZ10: 20 | CA10: 8 | CB10: 8 | CG10: 20 | CH10: 20 | CO10: 10 | CP10: 18 | CS10: =SUM(BN10:CR10) -> 104 | DD10: 8 | DF10: 3 | DG10: 3 | DK10: 3 | DL10: 10 | DM10: 6 | DY10: =SUM(CT10:DX10) -> 33 | EB10: 10 | EF10: 8 | EH10: 12 | EI10: 8 | EM10: 10 | EP10: 5 | EQ10: 5 | ET10: 11 | EU10: 5 | FB10: 24 | FC10: 3 | FD10: =SUM(DZ10:FC10) -> 101 | FE10: 6 | GJ10: =SUM(FE10:GI10) -> 6 | HO10: =SUM(GK10:HN10) -> 0 | IT10: 409 | IU10: =SUM(HP10:IT10) -> 409 | IV10: =SUM(AH10,BM10,CS10,DY10,FD10,GJ10,HO10,IU10) -> 779
A11: Связь графика КПО с картой КПО | B11: шт. | AH11: =SUM(C11:AG11) -> 0 | BM11: =SUM(AI11:BL11) -> 0 | CS11: =SUM(BN11:CR11) -> 0 | DY11: =SUM(CT11:DX11) -> 0 | FD11: =SUM(DZ11:FC11) -> 0 | GJ11: =SUM(FE11:GI11) -> 0 | HO11: =SUM(GK11:HN11) -> 0 | IT11: 220 | IU11: =SUM(HP11:IT11) -> 220 | IV11: =SUM(AH11,BM11,CS11,DY11,FD11,GJ11,HO11,IU11) -> 220
A12: Отрисовка фитингов в МПК Панорама | B12: шт. | AH12: =SUM(C12:AG12) -> 0 | AW12: 2 | BM12: =SUM(AI12:BL12) -> 2 | CS12: =SUM(BN12:CR12) -> 0 | DY12: =SUM(CT12:DX12) -> 0 | FD12: =SUM(DZ12:FC12) -> 0 | GJ12: =SUM(FE12:GI12) -> 0 | HO12: =SUM(GK12:HN12) -> 0 | IT12: 6 | IU12: =SUM(HP12:IT12) -> 6 | IV12: =SUM(AH12,BM12,CS12,DY12,FD12,GJ12,HO12,IU12) -> 8
A13: Нанесение подвалов в МПК "Панорама" | B13: шт. | C13: 115 | AH13: =SUM(C13:AG13) -> 115 | AW13: 12 | BM13: =SUM(AI13:BL13) -> 12 | CS13: =SUM(BN13:CR13) -> 0 | DN13: 34 | DS13: 26 | DT13: 26 | DU13: 21 | DX13: 11 | DY13: =SUM(CT13:DX13) -> 118 | DZ13: 19 | FD13: =SUM(DZ13:FC13) -> 19 | GJ13: =SUM(FE13:GI13) -> 0 | HO13: =SUM(GK13:HN13) -> 0 | IT13: 156 | IU13: =SUM(HP13:IT13) -> 156 | IV13: =SUM(AH13,BM13,CS13,DY13,FD13,GJ13,HO13,IU13) -> 420
A14: Исправление ошибок по целостности газопроводов | B14: шт. | AH14: =SUM(C14:AG14) -> 0 | BM14: =SUM(AI14:BL14) -> 0 | CS14: =SUM(BN14:CR14) -> 0 | DY14: =SUM(CT14:DX14) -> 0 | FD14: =SUM(DZ14:FC14) -> 0 | GJ14: =SUM(FE14:GI14) -> 0 | HO14: =SUM(GK14:HN14) -> 0 | IT14: 108 | IU14: =SUM(HP14:IT14) -> 108 | IV14: =SUM(AH14,BM14,CS14,DY14,FD14,GJ14,HO14,IU14) -> 108
A15: Заполнение карточки на кран на газопроводе-вводе | B15: шт. | C15: 135 | AH15: =SUM(C15:AG15) -> 135 | AJ15: 5 | AM15: 3 | AS15: 4 | AT15: 8 | AW15: 5 | AX15: 4 | BA15: 22 | BD15: 22 | BF15: 37 | BM15: =SUM(AI15:BL15) -> 110 | CP15: 4 | CS15: =SUM(BN15:CR15) -> 4 | CW15: 30 | CX15: 20 | CY15: 10 | CZ15: 12 | DC15: 13 | DD15: 38 | DE15: 11 | DF15: 7 | DG15: 13 | DK15: 13 | DL15: 5 | DM15: 13 | DN15: 30 | DS15: 10 | DT15: 26 | DU15: 19 | DX15: 41 | DY15: =SUM(CT15:DX15) -> 311 | DZ15: 26 | EA15: 19 | EC15: 13 | EH15: 8 | EI15: 37 | EM15: 31 | EN15: 25 | EO15: 24 | EP15: 15 | EQ15: 18 | EU15: 22 | EW15: 2 | FB15: 5 | FC15: 11 | FD15: =SUM(DZ15:FC15) -> 256 | FE15: 10 | FF15: 47 | GJ15: =SUM(FE15:GI15) -> 57 | HO15: =SUM(GK15:HN15) -> 0 | IT15: 750 | IU15: =SUM(HP15:IT15) -> 750 | IV15: =SUM(AH15,BM15,CS15,DY15,FD15,GJ15,HO15,IU15) -> 1623
A16: Демонтаж газопроводов | B16: Арх. № (пунктов) | AH16: =SUM(C16:AG16) -> 0 | AK16: 1 | BM16: =SUM(AI16:BL16) -> 1 | CO16: 3 | CS16: =SUM(BN16:CR16) -> 3 | DY16: =SUM(CT16:DX16) -> 0 | FD16: =SUM(DZ16:FC16) -> 0 | GJ16: =SUM(FE16:GI16) -> 0 | HO16: =SUM(GK16:HN16) -> 0 | IU16: =SUM(HP16:IT16) -> 0 | IV16: =SUM(AH16,BM16,CS16,DY16,FD16,GJ16,HO16,IU16) -> 4
A17: Инвентаризация запорных устройств | B17: шт. | C17: 12 | AH17: =SUM(C17:AG17) -> 12 | BM17: =SUM(AI17:BL17) -> 0 | IV17: =SUM(AH17,BM17,CS17,DY17,FD17,GJ17,HO17,IU17) -> 12
A18: Иные работы | B18: шт. | C18: 163 | AH18: =SUM(C18:AG18) -> 163 | AI18: 26 | AJ18: 26 | AK18: 20 | AL18: 40 | AM18: 10 | AN18: 50 | AP18: 20 | AQ18: 30 | AU18: 7 | AW18: 10 | AX18: 7 | AY18: 35 | AZ18: 45 | BA18: 20 | BD18: 10 | BE18: 15 | BM18: =SUM(AI18:BL18) -> 371 | CI18: 175 | CJ18: 35 | CQ18: 84 | CR18: 70 | CS18: =SUM(BN18:CR18) -> 364 | CV18: 230 | DY18: =SUM(CT18:DX18) -> 230 | EB18: 4 | FD18: =SUM(DZ18:FC18) -> 4 | GJ18: =SUM(FE18:GI18) -> 0 | HO18: =SUM(GK18:HN18) -> 0 | IU18: =SUM(HP18:IT18) -> 0 | IV18: =SUM(AH18,BM18,CS18,DY18,FD18,GJ18,HO18,IU18) -> 1132
AH19: =SUM(C19:AG19) -> 0 | BM19: =SUM(AI19:BL19) -> 0
AH20: =SUM(C20:AG20) -> 0 | BM20: =SUM(AI20:BL20) -> 0
AH21: =SUM(C21:AG21) -> 0 | BM21: =SUM(AI21:BL21) -> 0
AH22: =SUM(C22:AG22) -> 0 | BM22: =SUM(AI22:BL22) -> 0
AH23: =SUM(C23:AG23) -> 0 | BM23: =SUM(AI23:BL23) -> 0
B86: Оформление эксплуатационного паспорта в ПК УРГ
B87: Инвентаризация объектов ПК УРГ
B88: Прикрепление файлов в ПК УРГ
B89: Сканирование документации в ПК УРГ

Sheet Градусова
A1: Выполняемые работы | B1: Кол-во выполненной работы | C1: 46143 | D1: 46144 | E1: 46145 | F1: 46146 | G1: 46147 | H1: 46148 | I1: 46149 | J1: 46150 | K1: 46151 | L1: 46152 | M1: 46153 | N1: 46154 | O1: 46155 | P1: 46156 | Q1: 46157 | R1: 46158 | S1: 46159 | T1: 46160 | U1: 46161 | V1: 46162 | W1: 46163 | X1: 46164 | Y1: 46165 | Z1: 46166 | AA1: 46167 | AB1: 46168 | AC1: 46169 | AD1: 46170 | AE1: 46171 | AF1: 46172 | AG1: 46173 | AH1: Май | AI1: 46174 | AJ1: 46175 | AK1: 46176 | AL1: 46177 | AM1: 46178 | AN1: 46179 | AO1: 46180 | AP1: 46181 | AQ1: 46182 | AR1: 46183 | AS1: 46184 | AT1: 46185 | AU1: 46186 | AV1: 46187 | AW1: 46188 | AX1: 46189 | AY1: 46190 | AZ1: 46191 | BA1: 46192 | BB1: 46193 | BC1: 46194 | BD1: 46195 | BE1: 46196 | BF1: 46197 | BG1: 46198 | BH1: 46199 | BI1: 46200 | BJ1: 46201 | BK1: 46202 | BL1: 46203 | BM1: Июнь | BN1: 46204 | BO1: 46205 | BP1: 46206 | BQ1: 46207 | BR1: 46208 | BS1: 46209 | BT1: 46210 | BU1: 46211 | BV1: 46212 | BW1: 46213 | BX1: 46214 | BY1: 46215 | BZ1: 46216 | CA1: 46217 | CB1: 46218 | CC1: 46219 | CD1: 46220 | CE1: 46221 | CF1: 46222 | CG1: 46223 | CH1: 46224 | CI1: 46225 | CJ1: 46226 | CK1: 46227 | CL1: 46228 | CM1: 46229 | CN1: 46230 | CO1: 46231 | CP1: 46232 | CQ1: 46233 | CR1: 46234 | CS1: Июль | CT1: 46235 | CU1: 46236 | CV1: 46237 | CW1: 46238 | CX1: 46239 | CY1: 46240 | CZ1: 46241 | DA1: 46242 | DB1: 46243 | DC1: 46244 | DD1: 46245 | DE1: 46246 | DF1: 46247 | DG1: 46248 | DH1: 46249 | DI1: 46250 | DJ1: 46251 | DK1: 46252 | DL1: 46253 | DM1: 46254 | DN1: 46255 | DO1: 46256 | DP1: 46257 | DQ1: 46258 | DR1: 46259 | DS1: 46260 | DT1: 46261 | DU1: 46262 | DV1: 46263 | DW1: 46264 | DX1: 46265 | DY1: Август | DZ1: 46266 | EA1: 46267 | EB1: 46268 | EC1: 46269 | ED1: 46270 | EE1: 46271 | EF1: 46272 | EG1: 46273 | EH1: 46274 | EI1: 46275 | EJ1: 46276 | EK1: 46277 | EL1: 46278 | EM1: 46279 | EN1: 46280 | EO1: 46281 | EP1: 46282 | EQ1: 46283 | ER1: 46284 | ES1: 46285 | ET1: 46286 | EU1: 46287 | EV1: 46288 | EW1: 46289 | EX1: 46290 | EY1: 46291 | EZ1: 46292 | FA1: 46293 | FB1: 46294 | FC1: 46295 | FD1: Сентябрь | FE1: 46296 | FF1: 46297 | FG1: 46298 | FH1: 46299 | FI1: 46300 | FJ1: 46301 | FK1: 46302 | FL1: 46303 | FM1: 46304 | FN1: 46305 | FO1: 46306 | FP1: 46307 | FQ1: 46308 | FR1: 46309 | FS1: 46310 | FT1: 46311 | FU1: 46312 | FV1: 46313 | FW1: 46314 | FX1: 46315 | FY1: 46316 | FZ1: 46317 | GA1: 46318 | GB1: 46319 | GC1: 46320 | GD1: 46321 | GE1: 46322 | GF1: 46323 | GG1: 46324 | GH1: 46325 | GI1: 46326 | GJ1: Октябрь | GK1: 46327 | GL1: 46328 | GM1: 46329 | GN1: 46330 | GO1: 46331 | GP1: 46332 | GQ1: 46333 | GR1: 46334 | GS1: 46335 | GT1: 46336 | GU1: 46337 | GV1: 46338 | GW1: 46339 | GX1: 46340 | GY1: 46341 | GZ1: 46342 | HA1: 46343 | HB1: 46344 | HC1: 46345 | HD1: 46346 | HE1: 46347 | HF1: 46348 | HG1: 46349 | HH1: 46350 | HI1: 46351 | HJ1: 46352 | HK1: 46353 | HL1: 46354 | HM1: 46355 | HN1: 46356 | HO1: Ноябрь | HP1: 46357 | HQ1: 46358 | HR1: 46359 | HS1: 46360 | HT1: 46361 | HU1: 46362 | HV1: 46363 | HW1: 46364 | HX1: 46365 | HY1: 46366 | HZ1: 46367 | IA1: 46368 | IB1: 46369 | IC1: 46370 | ID1: 46371 | IE1: 46372 | IF1: 46373 | IG1: 46374 | IH1: 46375 | II1: 46376 | IJ1: 46377 | IK1: 46378 | IL1: 46379 | IM1: 46380 | IN1: 46381 | IO1: 46382 | IP1: 46383 | IQ1: 46384 | IR1: 46385 | IS1: 46386 | IT1: 46387 | IU1: Декабрь | IV1: Всё
A2: Создание нового объекта в АРМ "Наружные сети", МПК "Панорама", внесение графического изображения газопровода и смежных коммуникация, настройка связей, внесение электронного варианта ИТД | B2: м. | C2: 317 | AH2: =SUM(C2:AG2) -> 317 | AI2: 46.42 | AK2: 16.57 | AM2: 43.95 | AP2: 38.63 | AR2: 299.5 | AT2: 88.62 | AW2: 42.91 | AX2: 65.36 | BD2: 48.41 | BE2: 26.98 | BF2: 132.21 | BG2: 74.8 | BH2: 156.36 | BK2: 46.32 | BL2: 0.35 | BM2: =SUM(AI2:BL2) -> 1127.39 | BN2: 58.01 | BO2: 63.73 | BT2: 1.5 | BU2: 29.56 | CA2: 117.66 | CB2: 59.92 | CG2: 93.48 | CH2: 5.46 | CK2: 81.54 | CS2: =SUM(BN2:CR2) -> 510.86 | DK2: 59.12 | DL2: диспансеризация | DM2: 28.13 | DQ2: 93.04 | DR2: 89.66 | DS2: 11.65 | DY2: =SUM(CT2:DX2) -> 281.6 | EB2: 69.92 | EC2: 8.52 | EG2: 145.42 | EH2: 422.12 | EI2: 91.51 | EN2: 37.23 | EQ2: 94.66 | EU2: 74.2 | FD2: =SUM(DZ2:FC2) -> 943.58 | FE2: 32.94 | GJ2: =SUM(FE2:GI2) -> 32.94 | HO2: =SUM(GK2:HN2) -> 0 | IT2: 1500 | IU2: =SUM(HP2:IT2) -> 1500 | IV2: =SUM(AH2,BM2,CS2,DY2,FD2,GJ2,HO2,IU2) -> 4713.37
A3: Внесение в 7эг, МПК "Панорама" актов на ликвидацию | B3: шт. | C3: 29 | AH3: =SUM(C3:AG3) -> 29 | AK3: 1 | AM3: 1 | AT3: 1 | AW3: 2 | BM3: =SUM(AI3:BL3) -> 5 | BN3: 1 | BT3: 1 | BV3: 4 | CC3: 3 | CJ3: 3 | CS3: =SUM(BN3:CR3) -> 12 | DJ3: 3 | DK3: 1 | DM3: 8 | DN3: 1 | DQ3: 2 | DR3: 1 | DS3: 1 | DT3: 3 | DY3: =SUM(CT3:DX3) -> 20 | EA3: 1 | EB3: 1 | EF3: 1 | EH3: 1 | EP3: 1 | ET3: 1 | EU3: 1 | FC3: 1 | FD3: =SUM(DZ3:FC3) -> 8 | GJ3: =SUM(FE3:GI3) -> 0 | IT3: 51 | IU3: =SUM(HP3:IT3) -> 51 | IV3: =SUM(AH3,BM3,CS3,DY3,FD3,GJ3,HO3,IU3) -> 125
A4: Сканирование нарядов, размещение в электронный архив | B4: шт. | C4: 97 | AH4: =SUM(C4:AG4) -> 97 | AL4: 2 | AM4: 2 | AS4: 5 | AT4: 2 | AX4: 5 | BA4: 5 | BG4: 7 | BK4: 3 | BM4: =SUM(AI4:BL4) -> 31 | BN4: 19 | BS4: 3 | BT4: 17 | BV4: 4 | BW4: 4 | CA4: 5 | CC4: 6 | CG4: 4 | CH4: 2 | CJ4: 5 | CS4: =SUM(BN4:CR4) -> 69 | DJ4: 4 | DQ4: 10 | DR4: 1 | DU4: 14 | DY4: =SUM(CT4:DX4) -> 29 | EA4: 1 | EC4: 1 | EH4: 3 | EM4: 1 | EO4: 2 | EQ4: 1 | ET4: 2 | EU4: 5 | FB4: 3 | FC4: 5 | FD4: =SUM(DZ4:FC4) -> 24 | FF4: 3 | GJ4: =SUM(FE4:GI4) -> 3 | IT4: 128 | IU4: =SUM(HP4:IT4) -> 128 | IV4: =SUM(AH4,BM4,CS4,DY4,FD4,GJ4,HO4,IU4) -> 381
A5: Внесение нарядов в программные комплексы | B5: шт. | C5: 92 | AH5: =SUM(C5:AG5) -> 92 | AS5: 6 | AT5: 2 | AX5: 5 | BA5: 5 | BG5: 8 | BK5: 4 | BM5: =SUM(AI5:BL5) -> 30 | BN5: 14 | BS5: 2 | BT5: 17 | BV5: 6 | BW5: 3 | BZ5: 1 | CA5: 7 | CC5: 11 | CG5: 2 | CH5: 4 | CJ5: 4 | CS5: =SUM(BN5:CR5) -> 71 | DJ5: 3 | DQ5: 11 | DR5: 1 | DU5: 6 | DY5: =SUM(CT5:DX5) -> 21 | EA5: 1 | EC5: 1 | EH5: 5 | EM5: 2 | EO5: 1 | EQ5: 2 | ET5: 4 | EU5: 7 | FB5: 3 | FC5: 5 | FD5: =SUM(DZ5:FC5) -> 31 | FF5: 4 | GJ5: =SUM(FE5:GI5) -> 4 | IT5: 129 | IU5: =SUM(HP5:IT5) -> 129 | IV5: =SUM(AH5,BM5,CS5,DY5,FD5,GJ5,HO5,IU5) -> 378
A6: Исправление замечаний в 7эг | B6: шт. | C6: 16 | AH6: =SUM(C6:AG6) -> 16 | AL6: 2 | BD6: 1 | BM6: =SUM(AI6:BL6) -> 3 | BT6: 1 | BU6: 3 | BZ6: 2 | CC6: 3 | CD6: 3 | CJ6: 3 | CK6: 4 | CS6: =SUM(BN6:CR6) -> 19 | DJ6: 1 | DN6: 1 | DU6: 1 | DX6: 2 | DY6: =SUM(CT6:DX6) -> 5 | DZ6: 1 | EA6: 1 | EJ6: 2 | EM6: 3 | EO6: 4 | FD6: =SUM(DZ6:FC6) -> 11 | GJ6: =SUM(FE6:GI6) -> 0 | IT6: 30 | IU6: =SUM(HP6:IT6) -> 30 | IV6: =SUM(AH6,BM6,CS6,DY6,FD6,GJ6,HO6,IU6) -> 84
A7: Исправление замечаний в МПК Панорама | B7: шт. | C7: 11 | AH7: =SUM(C7:AG7) -> 11 | AJ7: 1 | AL7: 3 | AM7: 1 | AP7: 2 | AS7: 1 | BD7: 1 | BH7: 2 | BM7: =SUM(AI7:BL7) -> 11 | BS7: 1 | BT7: 2 | BU7: 2 | BV7: 1 | BZ7: 1 | CB7: 1 | CC7: 11 | CD7: 4 | CG7: 1 | CH7: 1 | CJ7: 3 | CS7: =SUM(BN7:CR7) -> 28 | DX7: 1 | DY7: =SUM(CT7:DX7) -> 1 | DZ7: 1 | EA7: 1 | EI7: 1 | EJ7: 2 | EM7: 4 | EN7: 4 | EO7: 2 | FD7: =SUM(DZ7:FC7) -> 15 | GJ7: =SUM(FE7:GI7) -> 0 | IT7: 31 | IU7: =SUM(HP7:IT7) -> 31 | IV7: =SUM(AH7,BM7,CS7,DY7,FD7,GJ7,HO7,IU7) -> 97
A8: Инвентаризация паспортов | B8: Арх. № (пунктов) | AH8: =SUM(C8:AG8) -> 0 | BM8: =SUM(AI8:BL8) -> 0 | CS8: =SUM(BN8:CR8) -> 0 | DM8: 4 | DU8: 1 | DY8: =SUM(CT8:DX8) -> 5 | ET8: 1 | FD8: =SUM(DZ8:FC8) -> 1 | GJ8: =SUM(FE8:GI8) -> 0 | IT8: 5 | IU8: =SUM(HP8:IT8) -> 5 | IV8: =SUM(AH8,BM8,CS8,DY8,FD8,GJ8,HO8,IU8) -> 11
A9: Сканирование документации (листов) | B9: шт. | C9: 443 | AH9: =SUM(C9:AG9) -> 443 | AI9: 6 | AJ9: 8 | AK9: 18 | AL9: 7 | AM9: 12 | AP9: 11 | AQ9: 15 | AS9: 14 | AT9: 21 | AW9: 7 | AX9: 16 | AZ9: 7 | BA9: 27 | BD9: 26 | BE9: 16 | BF9: 24 | BG9: 22 | BH9: 24 | BK9: 12 | BL9: 4 | BM9: =SUM(AI9:BL9) -> 297 | BN9: 23 | BO9: 15 | BT9: 4 | BU9: 14 | BV9: 17 | BW9: 2 | BZ9: 2 | CA9: 12 | CB9: 28 | CD9: 60 | CG9: 22 | CH9: 6 | CI9: 5 | CJ9: 19 | CK9: 9 | CS9: =SUM(BN9:CR9) -> 238 | DJ9: 2 | DK9: 15 | DM9: 46 | DN9: 60 | DQ9: 23 | DR9: 34 | DS9: 45 | DT9: 52 | DU9: 22 | DX9: 32 | DY9: =SUM(CT9:DX9) -> 331 | DZ9: 60 | EA9: 33 | EB9: 23 | EC9: 6 | EF9: 1 | EG9: 22 | EH9: 6 | EI9: 20 | EJ9: 31 | EM9: 22 | EN9: 55 | EO9: 39 | EP9: 16 | ET9: 4 | EU9: 20 | FB9: 5 | FC9: 100 | FD9: =SUM(DZ9:FC9) -> 463 | FE9: 95 | FF9: 37 | GJ9: =SUM(FE9:GI9) -> 132 | IT9: 433 | IU9: =SUM(HP9:IT9) -> 433 | IV9: =SUM(AH9,BM9,CS9,DY9,FD9,GJ9,HO9,IU9) -> 2337
A10: Прикрепление файлов итд в 7 ЭГ | B10: шт. | C10: 218 | AH10: =SUM(C10:AG10) -> 218 | AI10: 3 | AJ10: 4 | AK10: 8 | AL10: 5 | AM10: 6 | AP10: 5 | AQ10: 7 | AS10: 6 | AT10: 10 | AW10: 4 | AX10: 7 | BA10: 3 | BD10: 8 | BE10: 6 | BF10: 12 | BG10: 12 | BH10: 12 | BK10: 6 | BL10: 1 | BM10: =SUM(AI10:BL10) -> 125 | BN10: 11 | BO10: 6 | BT10: 1 | BU10: 9 | BV10: 11 | BW10: 2 | BZ10: 2 | CA10: 6 | CB10: 14 | CD10: 8 | CG10: 10 | CH10: 3 | CI10: 5 | CJ10: 19 | CK10: 3 | CS10: =SUM(BN10:CR10) -> 110 | DJ10: 1 | DK10: 6 | DM10: 13 | DN10: 20 | DQ10: 10 | DR10: 15 | DS10: 20 | DT10: 31 | DU10: 7 | DX10: 14 | DY10: =SUM(CT10:DX10) -> 137 | DZ10: 26 | EA10: 16 | EB10: 11 | EC10: 3 | EF10: 1 | EG10: 10 | EH10: 11 | EI10: 10 | EJ10: 19 | EM10: 33 | EN10: 33 | EO10: 21 | EP10: 9 | ET10: 1 | EU10: 8 | FB10: 3 | FC10: 48 | FD10: =SUM(DZ10:FC10) -> 263 | FE10: 46 | FF10: 16 | GJ10: =SUM(FE10:GI10) -> 62 | IT10: 409 | IU10: =SUM(HP10:IT10) -> 409 | IV10: =SUM(AH10,BM10,CS10,DY10,FD10,GJ10,HO10,IU10) -> 1324
A11: Связь графика КПО с картой КПО | B11: шт. | AH11: =SUM(C11:AG11) -> 0 | BM11: =SUM(AI11:BL11) -> 0 | CS11: =SUM(BN11:CR11) -> 0 | DY11: =SUM(CT11:DX11) -> 0 | FD11: =SUM(DZ11:FC11) -> 0 | GJ11: =SUM(FE11:GI11) -> 0 | IT11: 220 | IU11: =SUM(HP11:IT11) -> 220 | IV11: =SUM(AH11,BM11,CS11,DY11,FD11,GJ11,HO11,IU11) -> 220
A12: Отрисовка фитингов в МПК Панорама | B12: шт. | C12: 3 | AH12: =SUM(C12:AG12) -> 3 | AM12: 1 | BM12: =SUM(AI12:BL12) -> 1 | CS12: =SUM(BN12:CR12) -> 0 | DY12: =SUM(CT12:DX12) -> 0 | EH12: 1 | FC12: 2 | FD12: =SUM(DZ12:FC12) -> 3 | GJ12: =SUM(FE12:GI12) -> 0 | IT12: 6 | IU12: =SUM(HP12:IT12) -> 6 | IV12: =SUM(AH12,BM12,CS12,DY12,FD12,GJ12,HO12,IU12) -> 13
A13: Нанесение подвалов в МПК "Панорама" | B13: шт. | C13: 19 | AH13: =SUM(C13:AG13) -> 19 | AQ13: 3 | BM13: =SUM(AI13:BL13) -> 3 | CS13: =SUM(BN13:CR13) -> 0 | DY13: =SUM(CT13:DX13) -> 0 | FD13: =SUM(DZ13:FC13) -> 0 | GJ13: =SUM(FE13:GI13) -> 0 | IT13: 156 | IU13: =SUM(HP13:IT13) -> 156 | IV13: =SUM(AH13,BM13,CS13,DY13,FD13,GJ13,HO13,IU13) -> 178
A14: Исправление ошибок по целостности газопроводов | B14: шт. | C14: 196 | AH14: =SUM(C14:AG14) -> 196 | BM14: =SUM(AI14:BL14) -> 0 | CS14: =SUM(BN14:CR14) -> 0 | DY14: =SUM(CT14:DX14) -> 0 | FD14: =SUM(DZ14:FC14) -> 0 | GJ14: =SUM(FE14:GI14) -> 0 | IT14: 108 | IU14: =SUM(HP14:IT14) -> 108 | IV14: =SUM(AH14,BM14,CS14,DY14,FD14,GJ14,HO14,IU14) -> 304
A15: Заполнение карточки на кран на газопроводе-вводе | B15: шт. | AH15: =SUM(C15:AG15) -> 0 | AJ15: 4 | AK15: 1 | AL15: 33 | AM15: 2 | AP15: 2 | AQ15: 24 | AR15: 12 | AT15: 4 | AW15: 29 | AX15: 3 | BA15: 9 | BD15: 2 | BE15: 3 | BF15: 4 | BG15: 4 | BH15: 4 | BK15: 2 | BL15: 1 | BM15: =SUM(AI15:BL15) -> 143 | BN15: 5 | BO15: 3 | BT15: 3 | BW15: 1 | BZ15: 4 | CA15: 3 | CB15: 3 | CG15: 4 | CH15: 1 | CK15: 1 | CS15: =SUM(BN15:CR15) -> 28 | DJ15: 14 | DK15: 17 | DM15: 29 | DN15: 33 | DQ15: 9 | DR15: 4 | DS15: 23 | DT15: 39 | DU15: 52 | DX15: 53 | DY15: =SUM(CT15:DX15) -> 273 | DZ15: 29 | EA15: 17 | EB15: 4 | EC15: 27 | EF15: 54 | EG15: 4 | EH15: 2 | EI15: 5 | EJ15: 20 | EM15: 38 | EN15: 23 | EO15: 31 | EP15: 101 | EQ15: 27 | ET15: 63 | EU15: 13 | FB15: 92 | FC15: 22 | FD15: =SUM(DZ15:FC15) -> 572 | FE15: 21 | FF15: 68 | GJ15: =SUM(FE15:GI15) -> 89 | IT15: 750 | IU15: =SUM(HP15:IT15) -> 750 | IV15: =SUM(AH15,BM15,CS15,DY15,FD15,GJ15,HO15,IU15) -> 1855
A16: Демонтаж газопроводов | B16: Арх. № (пунктов) | AH16: =SUM(C16:AG16) -> 0 | BM16: =SUM(AI16:BL16) -> 0 | BN16: 1 | CS16: =SUM(BN16:CR16) -> 1 | DY16: =SUM(CT16:DX16) -> 0 | FD16: =SUM(DZ16:FC16) -> 0 | GJ16: =SUM(FE16:GI16) -> 0 | IU16: =SUM(HP16:IT16) -> 0 | IV16: =SUM(AH16,BM16,CS16,DY16,FD16,GJ16,HO16,IU16) -> 1
A17: Инвентаризация запорных устройств | B17: шт. | C17: 82 | AH17: =SUM(C17:AG17) -> 82 | AM17: 1 | BM17: =SUM(AI17:BL17) -> 1 | IV17: =SUM(AH17,BM17,CS17,DY17,FD17,GJ17,HO17,IU17) -> 83
A18: Иные работы | B18: шт. | C18: 117 | AH18: =SUM(C18:AG18) -> 117 | AI18: 36 | AJ18: 58 | AK18: 85 | AL18: 40 | AM18: 5 | AP18: 53 | AQ18: 32 | AW18: 25 | AX18: 39 | AY18: 60 | AZ18: 63 | BA18: 35 | BD18: 25 | BE18: 48 | BF18: 1 | BK18: 48 | BL18: 83 | BM18: =SUM(AI18:BL18) -> 736 | BO18: 12 | BS18: 77 | BU18: 25 | BV18: 37 | BW18: 66 | BZ18: 31 | CA18: 6 | CB18: 17 | CD18: 14 | CG18: 12 | CH18: 53 | CI18: 120 | CJ18: 100 | CK18: 29 | CS18: =SUM(BN18:CR18) -> 599 | DY18: =SUM(CT18:DX18) -> 0 | EB18: 3 | EI18: 1 | EO18: 1 | FD18: =SUM(DZ18:FC18) -> 5 | GJ18: =SUM(FE18:GI18) -> 0 | IU18: =SUM(HP18:IT18) -> 0 | IV18: =SUM(AH18,BM18,CS18,DY18,FD18,GJ18,HO18,IU18) -> 1457
AH19: =SUM(C19:AG19) -> 0 | BM19: =SUM(AI19:BL19) -> 0
AH20: =SUM(C20:AG20) -> 0 | BM20: =SUM(AI20:BL20) -> 0
AH21: =SUM(C21:AG21) -> 0 | BM21: =SUM(AI21:BL21) -> 0
AH22: =SUM(C22:AG22) -> 0 | BM22: =SUM(AI22:BL22) -> 0
AH23: =SUM(C23:AG23) -> 0 | BM23: =SUM(AI23:BL23) -> 0
B86: Оформление эксплуатационного паспорта в ПК УРГ
B87: Инвентаризация объектов ПК УРГ
B88: Прикрепление файлов в ПК УРГ
B89: Сканирование документации в ПК УРГ

Sheet Ксеневич
A1: Выполняемые работы | B1: Кол-во выполненной работы | C1: 46143 | D1: 46144 | E1: 46145 | F1: 46146 | G1: 46147 | H1: 46148 | I1: 46149 | J1: 46150 | K1: 46151 | L1: 46152 | M1: 46153 | N1: 46154 | O1: 46155 | P1: 46156 | Q1: 46157 | R1: 46158 | S1: 46159 | T1: 46160 | U1: 46161 | V1: 46162 | W1: 46163 | X1: 46164 | Y1: 46165 | Z1: 46166 | AA1: 46167 | AB1: 46168 | AC1: 46169 | AD1: 46170 | AE1: 46171 | AF1: 46172 | AG1: 46173 | AH1: Май | AI1: 46174 | AJ1: 46175 | AK1: 46176 | AL1: 46177 | AM1: 46178 | AN1: 46179 | AO1: 46180 | AP1: 46181 | AQ1: 46182 | AR1: 46183 | AS1: 46184 | AT1: 46185 | AU1: 46186 | AV1: 46187 | AW1: 46188 | AX1: 46189 | AY1: 46190 | AZ1: 46191 | BA1: 46192 | BB1: 46193 | BC1: 46194 | BD1: 46195 | BE1: 46196 | BF1: 46197 | BG1: 46198 | BH1: 46199 | BI1: 46200 | BJ1: 46201 | BK1: 46202 | BL1: 46203 | BM1: Июнь | BN1: 46204 | BO1: 46205 | BP1: 46206 | BQ1: 46207 | BR1: 46208 | BS1: 46209 | BT1: 46210 | BU1: 46211 | BV1: 46212 | BW1: 46213 | BX1: 46214 | BY1: 46215 | BZ1: 46216 | CA1: 46217 | CB1: 46218 | CC1: 46219 | CD1: 46220 | CE1: 46221 | CF1: 46222 | CG1: 46223 | CH1: 46224 | CI1: 46225 | CJ1: 46226 | CK1: 46227 | CL1: 46228 | CM1: 46229 | CN1: 46230 | CO1: 46231 | CP1: 46232 | CQ1: 46233 | CR1: 46234 | CS1: Июль | CT1: 46235 | CU1: 46236 | CV1: 46237 | CW1: 46238 | CX1: 46239 | CY1: 46240 | CZ1: 46241 | DA1: 46242 | DB1: 46243 | DC1: 46244 | DD1: 46245 | DE1: 46246 | DF1: 46247 | DG1: 46248 | DH1: 46249 | DI1: 46250 | DJ1: 46251 | DK1: 46252 | DL1: 46253 | DM1: 46254 | DN1: 46255 | DO1: 46256 | DP1: 46257 | DQ1: 46258 | DR1: 46259 | DS1: 46260 | DT1: 46261 | DU1: 46262 | DV1: 46263 | DW1: 46264 | DX1: 46265 | DY1: Август | DZ1: 46266 | EA1: 46267 | EB1: 46268 | EC1: 46269 | ED1: 46270 | EE1: 46271 | EF1: 46272 | EG1: 46273 | EH1: 46274 | EI1: 46275 | EJ1: 46276 | EK1: 46277 | EL1: 46278 | EM1: 46279 | EN1: 46280 | EO1: 46281 | EP1: 46282 | EQ1: 46283 | ER1: 46284 | ES1: 46285 | ET1: 46286 | EU1: 46287 | EV1: 46288 | EW1: 46289 | EX1: 46290 | EY1: 46291 | EZ1: 46292 | FA1: 46293 | FB1: 46294 | FC1: 46295 | FD1: Сентябрь | FE1: 46296 | FF1: 46297 | FG1: 46298 | FH1: 46299 | FI1: 46300 | FJ1: 46301 | FK1: 46302 | FL1: 46303 | FM1: 46304 | FN1: 46305 | FO1: 46306 | FP1: 46307 | FQ1: 46308 | FR1: 46309 | FS1: 46310 | FT1: 46311 | FU1: 46312 | FV1: 46313 | FW1: 46314 | FX1: 46315 | FY1: 46316 | FZ1: 46317 | GA1: 46318 | GB1: 46319 | GC1: 46320 | GD1: 46321 | GE1: 46322 | GF1: 46323 | GG1: 46324 | GH1: 46325 | GI1: 46326 | GJ1: Октябрь | GK1: 46327 | GL1: 46328 | GM1: 46329 | GN1: 46330 | GO1: 46331 | GP1: 46332 | GQ1: 46333 | GR1: 46334 | GS1: 46335 | GT1: 46336 | GU1: 46337 | GV1: 46338 | GW1: 46339 | GX1: 46340 | GY1: 46341 | GZ1: 46342 | HA1: 46343 | HB1: 46344 | HC1: 46345 | HD1: 46346 | HE1: 46347 | HF1: 46348 | HG1: 46349 | HH1: 46350 | HI1: 46351 | HJ1: 46352 | HK1: 46353 | HL1: 46354 | HM1: 46355 | HN1: 46356 | HO1: Ноябрь | HP1: 46357 | HQ1: 46358 | HR1: 46359 | HS1: 46360 | HT1: 46361 | HU1: 46362 | HV1: 46363 | HW1: 46364 | HX1: 46365 | HY1: 46366 | HZ1: 46367 | IA1: 46368 | IB1: 46369 | IC1: 46370 | ID1: 46371 | IE1: 46372 | IF1: 46373 | IG1: 46374 | IH1: 46375 | II1: 46376 | IJ1: 46377 | IK1: 46378 | IL1: 46379 | IM1: 46380 | IN1: 46381 | IO1: 46382 | IP1: 46383 | IQ1: 46384 | IR1: 46385 | IS1: 46386 | IT1: 46387 | IU1: Декабрь | IV1: Всё
A2: Создание нового объекта в АРМ "Наружные сети", МПК "Панорама", внесение графического изображения газопровода и смежных коммуникация, настройка связей, внесение электронного варианта ИТД | B2: м. | C2: 223.85 | AH2: =SUM(C2:AG2) -> 223.85 | AS2: 86.63 | AX2: 29.29 | BM2: =SUM(AI2:BL2) -> 115.92 | BS2: 25.84 | BU2: 96.14 | BV2: 28.85 | CD2: 63.55 | CG2: 27.94 | CH2: 33.91 | CK2: 48.05 | CN2: 71.61 | CO2: 65.33 | CP2: 63.61 | CS2: =SUM(BN2:CR2) -> 524.83 | CY2: 1.35 | CZ2: 71.85 | DC2: 43.07 | DJ2: 146.21 | DK2: 59.6 | DL2: 34.65 | DR2: 67.4 | DS2: 83.37 | DT2: 1.66 | DU2: 7.73 | DX2: 49.85 | DY2: =SUM(CT2:DX2) -> 566.74 | EB2: 20.02 | EC2: 39.53 | EG2: 8.29 | EH2: 17.73 | EI2: 27.84 | EM2: 18.72 | EN2: 49.61 | EQ2: 202.88 | ET2: 2.95 | EV2: 18.85 | FD2: =SUM(DZ2:FC2) -> 406.42 | GJ2: =SUM(FE2:GI2) -> 0 | HO2: =SUM(GK2:HN2) -> 0 | IT2: 1500 | IU2: =SUM(HP2:IT2) -> 1500 | IV2: =SUM(AH2,BM2,CS2,DY2,FD2,GJ2,HO2,IU2) -> 3337.76
A3: Внесение в 7эг, МПК "Панорама" актов на ликвидацию | B3: шт. | C3: 5 | AH3: =SUM(C3:AG3) -> 5 | BM3: =SUM(AI3:BL3) -> 0 | BZ3: 1 | CB3: 3 | CJ3: 1 | CS3: =SUM(BN3:CR3) -> 5 | DY3: =SUM(CT3:DX3) -> 0 | EW3: 4 | EX3: 1 | FD3: =SUM(DZ3:FC3) -> 5 | GJ3: =SUM(FE3:GI3) -> 0 | HO3: =SUM(GK3:HN3) -> 0 | IT3: 51 | IU3: =SUM(HP3:IT3) -> 51 | IV3: =SUM(AH3,BM3,CS3,DY3,FD3,GJ3,HO3,IU3) -> 66
A4: Сканирование нарядов, размещение в электронный архив | B4: шт. | C4: 55 | AH4: =SUM(C4:AG4) -> 55 | AL4: 1 | AY4: 18 | BA4: 7 | BM4: =SUM(AI4:BL4) -> 26 | BT4: 9 | BV4: 4 | BW4: 5 | CA4: 6 | CH4: 2 | CJ4: 3 | CO4: 1 | CQ4: 4 | CS4: =SUM(BN4:CR4) -> 34 | CV4: 3 | CX4: 2 | CY4: 4 | DD4: 5 | DE4: 10 | DF4: 9 | DG4: 3 | DJ4: 5 | DL4: 6 | DX4: 1 | DY4: =SUM(CT4:DX4) -> 48 | DZ4: 5 | EB4: 7 | EC4: 4 | EF4: 4 | EJ4: 9 | EM4: 7 | EO4: 14 | EP4: 8 | EW4: 11 | EX4: 1 | FD4: =SUM(DZ4:FC4) -> 70 | GJ4: =SUM(FE4:GI4) -> 0 | HO4: =SUM(GK4:HN4) -> 0 | IT4: 128 | IU4: =SUM(HP4:IT4) -> 128 | IV4: =SUM(AH4,BM4,CS4,DY4,FD4,GJ4,HO4,IU4) -> 361
A5: Внесение нарядов в программные комплексы | B5: шт. | C5: 55 | AH5: =SUM(C5:AG5) -> 55 | AL5: 1 | AY5: 18 | BA5: 7 | BM5: =SUM(AI5:BL5) -> 26 | BT5: 9 | BV5: 4 | BZ5: 6 | CB5: 6 | CH5: 2 | CJ5: 3 | CO5: 1 | CS5: =SUM(BN5:CR5) -> 31 | CV5: 3 | CX5: 2 | CY5: 4 | DD5: 5 | DE5: 10 | DF5: 9 | DG5: 3 | DJ5: 5 | DL5: 6 | DX5: 1 | DY5: =SUM(CT5:DX5) -> 48 | EA5: 5 | EB5: 7 | EC5: 1 | EF5: 4 | EJ5: 9 | EM5: 7 | EO5: 14 | EP5: 8 | EX5: 1 | FD5: =SUM(DZ5:FC5) -> 56 | GJ5: =SUM(FE5:GI5) -> 0 | HO5: =SUM(GK5:HN5) -> 0 | IT5: 129 | IU5: =SUM(HP5:IT5) -> 129 | IV5: =SUM(AH5,BM5,CS5,DY5,FD5,GJ5,HO5,IU5) -> 345
A6: Исправление замечаний в 7эг | B6: шт. | AH6: =SUM(C6:AG6) -> 0 | BM6: =SUM(AI6:BL6) -> 0 | CA6: 3 | CK6: 2 | CQ6: 4 | CS6: =SUM(BN6:CR6) -> 9 | DY6: =SUM(CT6:DX6) -> 0 | EP6: 1 | FD6: =SUM(DZ6:FC6) -> 1 | GJ6: =SUM(FE6:GI6) -> 0 | HO6: =SUM(GK6:HN6) -> 0 | IT6: 30 | IU6: =SUM(HP6:IT6) -> 30 | IV6: =SUM(AH6,BM6,CS6,DY6,FD6,GJ6,HO6,IU6) -> 40
A7: Исправление замечаний в МПК Панорама | B7: шт. | AH7: =SUM(C7:AG7) -> 0 | AJ7: 26 | AL7: 40 | BM7: =SUM(AI7:BL7) -> 66 | BW7: 4 | CA7: 3 | CI7: 5 | CJ7: 10 | CK7: 1 | CP7: 1 | CS7: =SUM(BN7:CR7) -> 24 | CZ7: 1 | DC7: 3 | DD7: 4 | DF7: 2 | DS7: 3 | DY7: =SUM(CT7:DX7) -> 13 | EP7: 2 | FD7: =SUM(DZ7:FC7) -> 2 | GJ7: =SUM(FE7:GI7) -> 0 | HO7: =SUM(GK7:HN7) -> 0 | IT7: 31 | IU7: =SUM(HP7:IT7) -> 31 | IV7: =SUM(AH7,BM7,CS7,DY7,FD7,GJ7,HO7,IU7) -> 136
A8: Инвентаризация паспортов | B8: Арх. № (пунктов) | AH8: =SUM(C8:AG8) -> 0 | BM8: =SUM(AI8:BL8) -> 0 | CK8: 1 | CS8: =SUM(BN8:CR8) -> 1 | DY8: =SUM(CT8:DX8) -> 0 | FD8: =SUM(DZ8:FC8) -> 0 | GJ8: =SUM(FE8:GI8) -> 0 | HO8: =SUM(GK8:HN8) -> 0 | IT8: 5 | IU8: =SUM(HP8:IT8) -> 5 | IV8: =SUM(AH8,BM8,CS8,DY8,FD8,GJ8,HO8,IU8) -> 6
A9: Сканирование документации (листов) | B9: шт. | C9: 69 | AH9: =SUM(C9:AG9) -> 69 | AY9: 10 | AZ9: 9 | BA9: 6 | BM9: =SUM(AI9:BL9) -> 25 | BS9: 2 | BU9: 8 | BV9: 9 | CA9: 20 | CC9: 16 | CD9: 20 | CG9: 20 | CJ9: 15 | CK9: 19 | CN9: 10 | CO9: 14 | CP9: 21 | CQ9: 20 | CS9: =SUM(BN9:CR9) -> 194 | CV9: 15 | CX9: 16 | CY9: 25 | DC9: 14 | DD9: 61 | DJ9: 16 | DK9: 15 | DL9: 7 | DQ9: 32 | DR9: 15 | DY9: =SUM(CT9:DX9) -> 216 | DZ9: 10 | EB9: 7 | EC9: 5 | EF9: 10 | EJ9: 62 | EM9: 36 | EO9: 14 | EP9: 8 | ET9: 4 | EV9: 61 | EW9: 32 | EX9: 1 | FD9: =SUM(DZ9:FC9) -> 250 | GJ9: =SUM(FE9:GI9) -> 0 | HO9: =SUM(GK9:HN9) -> 0 | IT9: 433 | IU9: =SUM(HP9:IT9) -> 433 | IV9: =SUM(AH9,BM9,CS9,DY9,FD9,GJ9,HO9,IU9) -> 1187
A10: Прикрепление файлов итд в 7 ЭГ | B10: шт. | C10: 49 | AH10: =SUM(C10:AG10) -> 49 | AY10: 10 | AZ10: 9 | BA10: 6 | BM10: =SUM(AI10:BL10) -> 25 | BS10: 2 | BU10: 4 | BV10: 4 | CA10: 5 | CC10: 3 | CD10: 6 | CG10: 2 | CH10: 3 | CJ10: 15 | CK10: 19 | CN10: 10 | CO10: 14 | CP10: 21 | CQ10: 20 | CS10: =SUM(BN10:CR10) -> 128 | CV10: 3 | CX10: 2 | CY10: 8 | CZ10: 7 | DC10: 8 | DG10: 3 | DJ10: 4 | DK10: 9 | DL10: 10 | DX10: 8 | DY10: =SUM(CT10:DX10) -> 62 | EA10: 3 | EB10: 10 | EC10: 3 | EJ10: 9 | EM10: 11 | EN10: 8 | EO10: 14 | EP10: 8 | ET10: 4 | EV10: 8 | EW10: 13 | FD10: =SUM(DZ10:FC10) -> 91 | GJ10: =SUM(FE10:GI10) -> 0 | HO10: =SUM(GK10:HN10) -> 0 | IT10: 409 | IU10: =SUM(HP10:IT10) -> 409 | IV10: =SUM(AH10,BM10,CS10,DY10,FD10,GJ10,HO10,IU10) -> 764
A11: Связь графика КПО с картой КПО | B11: шт. | AH11: =SUM(C11:AG11) -> 0 | BM11: =SUM(AI11:BL11) -> 0 | CS11: =SUM(BN11:CR11) -> 0 | DY11: =SUM(CT11:DX11) -> 0 | FD11: =SUM(DZ11:FC11) -> 0 | GJ11: =SUM(FE11:GI11) -> 0 | HO11: =SUM(GK11:HN11) -> 0 | IT11: 220 | IU11: =SUM(HP11:IT11) -> 220 | IV11: =SUM(AH11,BM11,CS11,DY11,FD11,GJ11,HO11,IU11) -> 220
A12: Отрисовка фитингов в МПК Панорама | B12: шт. | AH12: =SUM(C12:AG12) -> 0 | BM12: =SUM(AI12:BL12) -> 0 | CB12: 1 | CO12: 1 | CS12: =SUM(BN12:CR12) -> 2 | DY12: =SUM(CT12:DX12) -> 0 | FD12: =SUM(DZ12:FC12) -> 0 | GJ12: =SUM(FE12:GI12) -> 0 | HO12: =SUM(GK12:HN12) -> 0 | IT12: 6 | IU12: =SUM(HP12:IT12) -> 6 | IV12: =SUM(AH12,BM12,CS12,DY12,FD12,GJ12,HO12,IU12) -> 8
A13: Нанесение подвалов в МПК "Панорама" | B13: шт. | AH13: =SUM(C13:AG13) -> 0 | BM13: =SUM(AI13:BL13) -> 0 | CS13: =SUM(BN13:CR13) -> 0 | DY13: =SUM(CT13:DX13) -> 0 | FD13: =SUM(DZ13:FC13) -> 0 | GJ13: =SUM(FE13:GI13) -> 0 | HO13: =SUM(GK13:HN13) -> 0 | IT13: 156 | IU13: =SUM(HP13:IT13) -> 156 | IV13: =SUM(AH13,BM13,CS13,DY13,FD13,GJ13,HO13,IU13) -> 156
A14: Исправление ошибок по целостности газопроводов | B14: шт. | AH14: =SUM(C14:AG14) -> 0 | BM14: =SUM(AI14:BL14) -> 0 | CJ14: 9 | CS14: =SUM(BN14:CR14) -> 9 | DY14: =SUM(CT14:DX14) -> 0 | FD14: =SUM(DZ14:FC14) -> 0 | GJ14: =SUM(FE14:GI14) -> 0 | HO14: =SUM(GK14:HN14) -> 0 | IT14: 108 | IU14: =SUM(HP14:IT14) -> 108 | IV14: =SUM(AH14,BM14,CS14,DY14,FD14,GJ14,HO14,IU14) -> 117
A15: Заполнение карточки на кран на газопроводе-вводе | B15: шт. | C15: 31 | AH15: =SUM(C15:AG15) -> 31 | AZ15: 18 | BA15: 14 | BM15: =SUM(AI15:BL15) -> 32 | BU15: 2 | BV15: 2 | CG15: 2 | CH15: 3 | CK15: 2 | CN15: 1 | CO15: 1 | CP15: 3 | CS15: =SUM(BN15:CR15) -> 16 | CX15: 5 | CY15: 1 | CZ15: 2 | DC15: 2 | DD15: 6 | DE15: 27 | DF15: 18 | DG15: 10 | DK15: 3 | DL15: 8 | DR15: 3 | DS15: 2 | DX15: 4 | DY15: =SUM(CT15:DX15) -> 91 | EB15: 10 | EC15: 1 | EF15: 6 | EI15: 1 | EM15: 1 | EN15: 2 | EO15: 26 | EP15: 15 | EQ15: 2 | ET15: 1 | EV15: 1 | EW15: 4 | FD15: =SUM(DZ15:FC15) -> 70 | GJ15: =SUM(FE15:GI15) -> 0 | HO15: =SUM(GK15:HN15) -> 0 | IT15: 750 | IU15: =SUM(HP15:IT15) -> 750 | IV15: =SUM(AH15,BM15,CS15,DY15,FD15,GJ15,HO15,IU15) -> 990
A16: Демонтаж газопроводов | B16: Арх. № (пунктов) | AH16: =SUM(C16:AG16) -> 0 | BM16: =SUM(AI16:BL16) -> 0 | CS16: =SUM(BN16:CR16) -> 0 | DY16: =SUM(CT16:DX16) -> 0 | FD16: =SUM(DZ16:FC16) -> 0 | GJ16: =SUM(FE16:GI16) -> 0 | HO16: =SUM(GK16:HN16) -> 0 | IU16: =SUM(HP16:IT16) -> 0 | IV16: =SUM(AH16,BM16,CS16,DY16,FD16,GJ16,HO16,IU16) -> 0
A17: Инвентаризация запорных устройств | B17: шт. | C17: 24 | AH17: =SUM(C17:AG17) -> 24 | BM17: =SUM(AI17:BL17) -> 0 | CS17: =SUM(BN17:CR17) -> 0 | IV17: =SUM(AH17,BM17,CS17,DY17,FD17,GJ17,HO17,IU17) -> 24
A18: Иные работы | B18: шт. | AH18: =SUM(C18:AG18) -> 0 | BM18: =SUM(AI18:BL18) -> 0 | CC18: 7 | CD18: 8 | CQ18: 50 | CR18: 220 | CS18: =SUM(BN18:CR18) -> 285 | CV18: 716 | CW18: 1129 | CX18: 512 | DM18: 170 | DN18: 155 | DY18: =SUM(CT18:DX18) -> 2682 | FD18: =SUM(DZ18:FC18) -> 0 | GJ18: =SUM(FE18:GI18) -> 0 | HO18: =SUM(GK18:HN18) -> 0 | IU18: =SUM(HP18:IT18) -> 0 | IV18: =SUM(AH18,BM18,CS18,DY18,FD18,GJ18,HO18,IU18) -> 2967
AH19: =SUM(C19:AG19) -> 0 | BM19: =SUM(AI19:BL19) -> 0
AH20: =SUM(C20:AG20) -> 0 | BM20: =SUM(AI20:BL20) -> 0
AH21: =SUM(C21:AG21) -> 0 | BM21: =SUM(AI21:BL21) -> 0
AH22: =SUM(C22:AG22) -> 0 | BM22: =SUM(AI22:BL22) -> 0
AH23: =SUM(C23:AG23) -> 0 | BM23: =SUM(AI23:BL23) -> 0
B86: Оформление эксплуатационного паспорта в ПК УРГ
B87: Инвентаризация объектов ПК УРГ
B88: Прикрепление файлов в ПК УРГ
B89: Сканирование документации в ПК УРГ

Sheet Кошель
A1: Выполняемые работы | B1: Кол-во выполненной работы | C1: 46143 | D1: 46144 | E1: 46145 | F1: 46146 | G1: 46147 | H1: 46148 | I1: 46149 | J1: 46150 | K1: 46151 | L1: 46152 | M1: 46153 | N1: 46154 | O1: 46155 | P1: 46156 | Q1: 46157 | R1: 46158 | S1: 46159 | T1: 46160 | U1: 46161 | V1: 46162 | W1: 46163 | X1: 46164 | Y1: 46165 | Z1: 46166 | AA1: 46167 | AB1: 46168 | AC1: 46169 | AD1: 46170 | AE1: 46171 | AF1: 46172 | AG1: 46173 | AH1: Май | AI1: 46174 | AJ1: 46175 | AK1: 46176 | AL1: 46177 | AM1: 46178 | AN1: 46179 | AO1: 46180 | AP1: 46181 | AQ1: 46182 | AR1: 46183 | AS1: 46184 | AT1: 46185 | AU1: 46186 | AV1: 46187 | AW1: 46188 | AX1: 46189 | AY1: 46190 | AZ1: 46191 | BA1: 46192 | BB1: 46193 | BC1: 46194 | BD1: 46195 | BE1: 46196 | BF1: 46197 | BG1: 46198 | BH1: 46199 | BI1: 46200 | BJ1: 46201 | BK1: 46202 | BL1: 46203 | BM1: Июнь | BN1: 46204 | BO1: 46205 | BP1: 46206 | BQ1: 46207 | BR1: 46208 | BS1: 46209 | BT1: 46210 | BU1: 46211 | BV1: 46212 | BW1: 46213 | BX1: 46214 | BY1: 46215 | BZ1: 46216 | CA1: 46217 | CB1: 46218 | CC1: 46219 | CD1: 46220 | CE1: 46221 | CF1: 46222 | CG1: 46223 | CH1: 46224 | CI1: 46225 | CJ1: 46226 | CK1: 46227 | CL1: 46228 | CM1: 46229 | CN1: 46230 | CO1: 46231 | CP1: 46232 | CQ1: 46233 | CR1: 46234 | CS1: Июль | CT1: 46235 | CU1: 46236 | CV1: 46237 | CW1: 46238 | CX1: 46239 | CY1: 46240 | CZ1: 46241 | DA1: 46242 | DB1: 46243 | DC1: 46244 | DD1: 46245 | DE1: 46246 | DF1: 46247 | DG1: 46248 | DH1: 46249 | DI1: 46250 | DJ1: 46251 | DK1: 46252 | DL1: 46253 | DM1: 46254 | DN1: 46255 | DO1: 46256 | DP1: 46257 | DQ1: 46258 | DR1: 46259 | DS1: 46260 | DT1: 46261 | DU1: 46262 | DV1: 46263 | DW1: 46264 | DX1: 46265 | DY1: Август | DZ1: 46266 | EA1: 46267 | EB1: 46268 | EC1: 46269 | ED1: 46270 | EE1: 46271 | EF1: 46272 | EG1: 46273 | EH1: 46274 | EI1: 46275 | EJ1: 46276 | EK1: 46277 | EL1: 46278 | EM1: 46279 | EN1: 46280 | EO1: 46281 | EP1: 46282 | EQ1: 46283 | ER1: 46284 | ES1: 46285 | ET1: 46286 | EU1: 46287 | EV1: 46288 | EW1: 46289 | EX1: 46290 | EY1: 46291 | EZ1: 46292 | FA1: 46293 | FB1: 46294 | FC1: 46295 | FD1: Сентябрь | FE1: 46296 | FF1: 46297 | FG1: 46298 | FH1: 46299 | FI1: 46300 | FJ1: 46301 | FK1: 46302 | FL1: 46303 | FM1: 46304 | FN1: 46305 | FO1: 46306 | FP1: 46307 | FQ1: 46308 | FR1: 46309 | FS1: 46310 | FT1: 46311 | FU1: 46312 | FV1: 46313 | FW1: 46314 | FX1: 46315 | FY1: 46316 | FZ1: 46317 | GA1: 46318 | GB1: 46319 | GC1: 46320 | GD1: 46321 | GE1: 46322 | GF1: 46323 | GG1: 46324 | GH1: 46325 | GI1: 46326 | GJ1: Октябрь | GK1: 46327 | GL1: 46328 | GM1: 46329 | GN1: 46330 | GO1: 46331 | GP1: 46332 | GQ1: 46333 | GR1: 46334 | GS1: 46335 | GT1: 46336 | GU1: 46337 | GV1: 46338 | GW1: 46339 | GX1: 46340 | GY1: 46341 | GZ1: 46342 | HA1: 46343 | HB1: 46344 | HC1: 46345 | HD1: 46346 | HE1: 46347 | HF1: 46348 | HG1: 46349 | HH1: 46350 | HI1: 46351 | HJ1: 46352 | HK1: 46353 | HL1: 46354 | HM1: 46355 | HN1: 46356 | HO1: Ноябрь | HP1: 46357 | HQ1: 46358 | HR1: 46359 | HS1: 46360 | HT1: 46361 | HU1: 46362 | HV1: 46363 | HW1: 46364 | HX1: 46365 | HY1: 46366 | HZ1: 46367 | IA1: 46368 | IB1: 46369 | IC1: 46370 | ID1: 46371 | IE1: 46372 | IF1: 46373 | IG1: 46374 | IH1: 46375 | II1: 46376 | IJ1: 46377 | IK1: 46378 | IL1: 46379 | IM1: 46380 | IN1: 46381 | IO1: 46382 | IP1: 46383 | IQ1: 46384 | IR1: 46385 | IS1: 46386 | IT1: 46387 | IU1: Декабрь | IV1: Всё
A2: Создание нового объекта в АРМ "Наружные сети", МПК "Панорама", внесение графического изображения газопровода и смежных коммуникация, настройка связей, внесение электронного варианта ИТД | B2: м. | AH2: =SUM(C2:AG2) -> 0 | BM2: =SUM(AI2:BL2) -> 0 | CS2: =SUM(BN2:CR2) -> 0 | DY2: =SUM(CT2:DX2) -> 0 | FD2: =SUM(DZ2:FC2) -> 0 | GJ2: =SUM(FE2:GI2) -> 0 | HO2: =SUM(GK2:HN2) -> 0 | IU2: =SUM(HP2:IT2) -> 0 | IV2: =SUM(AH2,BM2,CS2,DY2,FD2,GJ2,HO2,IU2) -> 0
A3: Внесение в 7эг, МПК "Панорама" актов на ликвидацию | B3: шт. | AH3: =SUM(C3:AG3) -> 0 | BM3: =SUM(AI3:BL3) -> 0 | CS3: =SUM(BN3:CR3) -> 0 | DY3: =SUM(CT3:DX3) -> 0 | FD3: =SUM(DZ3:FC3) -> 0 | GJ3: =SUM(FE3:GI3) -> 0 | HO3: =SUM(GK3:HN3) -> 0 | IU3: =SUM(HP3:IT3) -> 0 | IV3: =SUM(AH3,BM3,CS3,DY3,FD3,GJ3,HO3,IU3) -> 0
A4: Сканирование нарядов, размещение в электронный архив | B4: шт. | AH4: =SUM(C4:AG4) -> 0 | BM4: =SUM(AI4:BL4) -> 0 | CS4: =SUM(BN4:CR4) -> 0 | DY4: =SUM(CT4:DX4) -> 0 | FD4: =SUM(DZ4:FC4) -> 0 | GJ4: =SUM(FE4:GI4) -> 0 | HO4: =SUM(GK4:HN4) -> 0 | IU4: =SUM(HP4:IT4) -> 0 | IV4: =SUM(AH4,BM4,CS4,DY4,FD4,GJ4,HO4,IU4) -> 0
A5: Внесение нарядов в программные комплексы | B5: шт. | AH5: =SUM(C5:AG5) -> 0 | BM5: =SUM(AI5:BL5) -> 0 | CS5: =SUM(BN5:CR5) -> 0 | DY5: =SUM(CT5:DX5) -> 0 | FD5: =SUM(DZ5:FC5) -> 0 | GJ5: =SUM(FE5:GI5) -> 0 | HO5: =SUM(GK5:HN5) -> 0 | IU5: =SUM(HP5:IT5) -> 0 | IV5: =SUM(AH5,BM5,CS5,DY5,FD5,GJ5,HO5,IU5) -> 0
A6: Исправление замечаний в 7эг | B6: шт. | AH6: =SUM(C6:AG6) -> 0 | BM6: =SUM(AI6:BL6) -> 0 | CS6: =SUM(BN6:CR6) -> 0 | DY6: =SUM(CT6:DX6) -> 0 | FD6: =SUM(DZ6:FC6) -> 0 | GJ6: =SUM(FE6:GI6) -> 0 | HO6: =SUM(GK6:HN6) -> 0 | IU6: =SUM(HP6:IT6) -> 0 | IV6: =SUM(AH6,BM6,CS6,DY6,FD6,GJ6,HO6,IU6) -> 0
A7: Исправление замечаний в МПК Панорама | B7: шт. | AH7: =SUM(C7:AG7) -> 0 | BM7: =SUM(AI7:BL7) -> 0 | CS7: =SUM(BN7:CR7) -> 0 | DY7: =SUM(CT7:DX7) -> 0 | FD7: =SUM(DZ7:FC7) -> 0 | GJ7: =SUM(FE7:GI7) -> 0 | HO7: =SUM(GK7:HN7) -> 0 | IU7: =SUM(HP7:IT7) -> 0 | IV7: =SUM(AH7,BM7,CS7,DY7,FD7,GJ7,HO7,IU7) -> 0
A8: Инвентаризация паспортов | B8: Арх. № (пунктов) | AH8: =SUM(C8:AG8) -> 0 | BM8: =SUM(AI8:BL8) -> 0 | CS8: =SUM(BN8:CR8) -> 0 | DY8: =SUM(CT8:DX8) -> 0 | FD8: =SUM(DZ8:FC8) -> 0 | GJ8: =SUM(FE8:GI8) -> 0 | HO8: =SUM(GK8:HN8) -> 0 | IU8: =SUM(HP8:IT8) -> 0 | IV8: =SUM(AH8,BM8,CS8,DY8,FD8,GJ8,HO8,IU8) -> 0
A9: Сканирование документации (листов) | B9: шт. | C9: 120 | K9: 10 | L9: 6 | M9: 8 | N9: 20 | Q9: 38 | R9: 30 | AH9: =SUM(C9:AG9) -> 232 | AQ9: 10 | AR9: 6 | AS9: 8 | AT9: 20 | AW9: 38 | AX9: 30 | AY9: 43 | AZ9: 56 | BA9: 52 | BD9: 36 | BE9: 47 | BF9: 43 | BG9: 45 | BH9: 34 | BK9: 46 | BL9: 53 | BM9: =SUM(AI9:BL9) -> 567 | BN9: 69 | BO9: 43 | BS9: 38 | BT9: 52 | BU9: 36 | BV9: 42 | BW9: 47 | BZ9: 94 | CA9: 51 | CB9: 42 | CC9: 47 | CD9: 44 | CG9: 60 | CH9: 32 | CI9: 27 | CJ9: 39 | CK9: 37 | CN9: 41 | CO9: 37 | CP9: 34 | CQ9: 31 | CR9: 35 | CS9: =SUM(BN9:CR9) -> 978 | CT9: 4 | CU9: 0 | CV9: 0 | CW9: 32 | CX9: 43 | CY9: 35 | CZ9: 29 | DC9: 37 | DD9: 41 | DE9: 45 | DF9: 43 | DG9: 39 | DH9: 33 | DK9: 37 | DL9: 22 | DM9: 47 | DN9: 33 | DQ9: 41 | DR9: 53 | DS9: 44 | DT9: 39 | DU9: 30 | DX9: 38 | DY9: =SUM(CT9:DX9) -> 765 | DZ9: 43 | EA9: 42 | EB9: 33 | EC9: 29 | EF9: 35 | EG9: 28 | EH9: 43 | EI9: 39 | EJ9: 32 | EM9: 31 | EN9: 37 | EO9: 41 | EP9: 47 | EQ9: 34 | ET9: 42 | EU9: 49 | EV9: 46 | EW9: 36 | EX9: 29 | FA9: 39 | FB9: 45 | FC9: 39 | FD9: =SUM(DZ9:FC9) -> 839 | FE9: 21 | GJ9: =SUM(FE9:GI9) -> 21 | HO9: =SUM(GK9:HN9) -> 0 | IU9: =SUM(HP9:IT9) -> 0 | IV9: =SUM(AH9,BM9,CS9,DY9,FD9,GJ9,HO9,IU9) -> 3402
